Workbook

Sheet DATA
A1: EMP NAME | B1: Euro-CB Phils. Inc. | E1: =CONCATENATE("EMPLOYEE COUNT ",(COUNT(BJ9:BJ25548))) | F1: SSS NUMBER | I1: ME-5 # / OR # | K1: QUARTER | M1: GSALLOTED | N1: MONTH | P1: *100 | R1: TXT $ | T1: REG/ADD | U1: R | V1: A | W1: M | X1: F | BI1: TOTAL PS | BS1: =SUM(BG9:BG10011) | BU1: LINKS
A2: ADDRESS | E2: =IF(M5=0," ",IF(M5>0,"REPORT OVERPAYMENT",IF(M5<0,"REPORT UNDERPAYMENT"))) | F2: TIN | G2: TIN-112-4444 | I2: AMOUNT PAID | K2: =IF(E5<=3,1,IF(E5<=6,2,IF(E5<=9,3,IF(E5<=12,4)))) | L2: =IF(K2=1,1,IF(K2<5,0)) | M2: =BG2-BS1-BS2 | N2: =IF(E5>=7,0,IF(E5=1,"JANUARY",IF(E5=2,"FEBRUARY",IF(E5=3,"MARCH",IF(E5=4,"APRIL",IF(E5=5,"MAY",IF(E5=6,"JUNE"))))))) | P2: =BG2*100 | R2: =P2 | T2: =FALSE() | U2: EMP TYPE | V2: EMP TYPE | W2: 2004 | X2: 2005 | Y2: 2006 | Z2: 2007 | AA2: 2008 | AB2: 2009 | AC2: 2010 | AD2: 2011 | AE2: 2012 | AF2: 2013 | AG2: 2014 | AH2: 2015 | BI2: =IF(E3="PRIVATE","TOTAL ES",IF(E3="HOUSEHOLD","TOTAL ES",IF(E3="GOVERNMENT","TOTAL GS",0))) | BP2: NE | BS2: =SUM(BH9:BH10011) | BU2: PRINT OUT RF1
A3: PEN | D3: EMPLOYER TYPE | E3: PRIVATE | F3: ALLOTED GS | I3: DATE PAID | K3: TYPE OF REPORT | L3: =IF(K2=2,1,IF(K2<5,0)) | M3: =BG2-BS1-BS3 | N3: =IF(E5<=6,0,IF(E5=7,"JULY",IF(E5=8,"AUGUST",IF(E5=9,"SEPTEMBER",IF(E5=10,"OCTOBER",IF(E5=11,"NOVEMBER",IF(E5=12,"DECEMBER"))))))) | P3: =BS3*100 | R3: =P3 | T3: COUNT | U3: =IF(E3="PRIVATE",1,0) | V3: PRIVATE | Y3: 7306 | BI3: =IF(F6=0,"NO ALLOTED GS",IF(F6>0,"TOTAL ALLOTED")) | BP3: NH | BS3: =SUM(BI9:BI10011) | BU3: SAVE TXT
A4: TEL # | D4: YEAR | E4: 2015 | F4: PREPARED BY | G4: Regulus Berdin | I4: APPLICABLE MONTH | K4: =IF(E6="R",TRUE(),IF(E6="A",FALSE())) | L4: =IF(K2=3,1,IF(K2<5,0)) | M4: OVER/UNDER | N4: =IF(N2=0,N3,IF(N3=0,N2,0)) | P4: =BS1*2 | R4: =P4*100 | T4: =COUNTIF(BG9:BG25548,">0") | U4: =IF(E3="GOVERNMENT",1,0) | V4: GOVERNMENT | Y4: 41274 | BG4: =N4 | BI4: TOTAL ARREARS | BP4: SP | BS4: =IF(F6=0,0,IF(F6>0,BS1-BS3)) | BU4: PRINT OUT RF1a
A5: INCHARGE | D5: MONTH | E5: 12 | F5: DESIGNATION | G5: Programmer | I5: TOTAL RF-1 | K5: =IF(E6="R",FALSE(),IF(E6="A",TRUE())) | L5: =IF(K2=4,1,IF(K2<5,0)) | M5: =IF(F6=0,M2,IF(F6>0,M3)) | P5: =BS5*100 | R5: =P5 | T5: =COUNTIF(BH9:BH25548,">0") | U5: =IF(E3="HOUSEHOLD",1,0) | V5: HOUSEHOLD | BG5: =IF(BS3=0,BS5,IF(BS3>0,BS6)) | BI5: =CONCATENATE(BI1," ","&"," ",BI2) | BS5: =BS1+BS2 | BU5: SAVE TXTa
A6: POSITION | D6: TYPE OF REPORT | E6: R | I6: OVER/UNDER | K6: =FALSE() | L6: =IF(K3=4,1,IF(K3<5,0)) | M6: =IF(F7=0,M3,IF(F7>0,M4)) | P6: =BS6*100 | R6: =P6 | T6: =COUNTIF(BI9:BI25548,">0") | U6: =SUM(U3:U4) | BG6: =IF(F6>0,BG2-BS6,IF(F6=0,BG2-BS5)) | BI6: =CONCATENATE(BI1," ","+"," ",BI3) | BS6: =BS1+BS3
A7: EMAIL | D7: DATE PREPARED | E7: =NOW() | F7: PHILHEALTH NO | G7: DATE OF BIRTH | H7: SEX | I7: SALARY | J7: SB | BG7: PS | BH7: =IF(E3="PRIVATE","ES",IF(E3="HOUSEHOLD","ES",IF(E3="GOVERNMENT","GS",0))) | BI7: ALLOTED | BS7: REMARKS | BT7: DATE
A8: # OF EE'S | B8: LAST NAME | C8: SUFFIX | D8: FIRST NAME | E8: MIDDLE NAME | K8: =E5 | L8: =E4 | M8: =G3 | N8: 1-6 | O8: 7-11 | P8: 12-17 | Q8: 1-8 | R8: 9-12 | S8: 1-6 | T8: 7-11 | U8: 12-17 | V8: 1-8 | W8: 9-16 | X8: 17 | Y8: 1-6 | Z8: 7-11 | AA8: 12-17 | AB8: 18-22 | AC8: 1-8 | AD8: 9-16 | AE8: 17-22 | AF8: 1-6 | AG8: 7-11 | AH8: 12-17 | AI8: 18-23 | AJ8: 24-27 | AK8: 1-8 | AL8: 9-16 | AM8: 17-24 | AN8: 25-27 | AO8: 1-6 | AP8: 7-11 | AQ8: 12-17 | AR8: 18-23 | AS8: 24-29 | AT8: 1-8 | AU8: 9-16 | AV8: 17-24 | AW8: 25-29 | AX8: 1-6 | AY8: 7-11 | AZ8: 12-17 | BA8: 18-23 | BB8: 24-28 | BC8: 1-8 | BD8: 9-16 | BE8: 17-24 | BF8: 25-28 | BJ8: EMPLOYEE INFO | BO8: REMARKS | BQ8: BDATE | BR8: DATE
A9: 1 | J9: =IF(L9=2008,AF9+AG9+AH9+AI9+AJ9,IF(L9=2009,AF9+AG9+AH9+AI9+AJ9,IF(L9=2010,AF9+AG9+AH9+AI9+AJ9,IF(L9=2011,AF9+AG9+AH9+AI9+AJ9,IF(L9=2012,AF9+AG9+AH9+AI9+AJ9,IF(L9=2013,AO9+AP9+AQ9+AR9+AS9,IF(L9=2014,AX9+AY9+AZ9+BA9+BB9,IF(L9=2015,AX9+AY9+AZ9+BA9+BB9)))))))) | K9: =K8 | L9: =L8 | M9: =M8 | N9: =IF(I9=0,"0",IF(I9<=4999.99,"1",IF(I9<=5999.99,"2",IF(I9<=6999.99,"3",IF(I9<=7999.99,"4",IF(I9<=8999.99,"5",IF(I9<=9999.99,"6",IF(I9>=9999.99,"0",0)))))))) | O9: =IF(I9<=9999.99,"0",IF(I9<=10999.99,"7",IF(I9<=11999.99,"8",IF(I9<=12999.99,"9",IF(I9<=13999.99,"10",IF(I9<=14999.99,"11",IF(I9>=14999.99,"0"))))))) | P9: =IF(I9<=14999.99,"0",IF(I9>=15000,"12")) | Q9: =IF(J9=1,"50",IF(J9=2,"62.50",IF(J9=3,"75",IF(J9=4,"87.5",IF(J9=5,"100",IF(J9=6,"112.50",IF(J9=7,"125",IF(J9=8,"137.50",0)))))))) | R9: =IF(J9=9,"150",IF(J9=10,"162.50",IF(J9=11,"175",IF(J9=12,"187.50",0)))) | S9: =IF(I9=0,"0",IF(I9<=4999.99,"1",IF(I9<=5999.99,"2",IF(I9<=6999.99,"3",IF(I9<=7999.99,"4",IF(I9<=8999.99,"5",IF(I9<=9999.99,"6",IF(I9>=9999.99,"0",0)))))))) | T9: =IF(I9<=9999.99,"0",IF(I9<=10999.99,"7",IF(I9<=11999.99,"8",IF(I9<=12999.99,"9",IF(I9<=13999.99,"10",IF(I9<=14999.99,"11",IF(I9>=14999.99,"0"))))))) | U9: =IF(I9<=14999.99,"0",IF(I9<=15999.99,"12",IF(I9<=16999.99,"13",IF(I9<=17999.99,"14",IF(I9<=18999.99,"15",IF(I9<=19999.99,"16",IF(I9>=20000,"17"))))))) | V9: =IF(J9=1,"50",IF(J9=2,"62.50",IF(J9=3,"75",IF(J9=4,"87.5",IF(J9=5,"100",IF(J9=6,"112.50",IF(J9=7,"125",IF(J9=8,"137.50",0)))))))) | W9: =IF(J9=9,"150",IF(J9=10,"162.50",IF(J9=11,"175",IF(J9=12,"187.50",IF(J9=13,"200",IF(J9=14,"212.5",IF(J9=15,"225",IF(J9=16,"237.5",0)))))))) | X9: =IF(J9=17,"250",0) | Y9: =IF(I9=0,"0",IF(I9<=4999.99,"1",IF(I9<=5999.99,"2",IF(I9<=6999.99,"3",IF(I9<=7999.99,"4",IF(I9<=8999.99,"5",IF(I9<=9999.99,"6",IF(I9>=9999.99,"0",0)))))))) | Z9: =IF(I9<=9999.99,"0",IF(I9<=10999.99,"7",IF(I9<=11999.99,"8",IF(I9<=12999.99,"9",IF(I9<=13999.99,"10",IF(I9<=14999.99,"11",IF(I9>=14999.99,"0"))))))) | AA9: =IF(I9<=14999.99,"0",IF(I9<=15999.99,"12",IF(I9<=16999.99,"13",IF(I9<=17999.99,"14",IF(I9<=18999.99,"15",IF(I9<=19999.99,"16",IF(I9<=20999.99,"17",IF(I9>=20999.99,"0")))))))) | AB9: =IF(I9<=20999.99,"0",IF(I9<=21999.99,"18",IF(I9<=22999.99,"19",IF(I9<=23999.99,"20",IF(I9<=24999.99,"21",IF(I9>=25000,"22")))))) | AC9: =IF(J9=1,"50",IF(J9=2,"62.50",IF(J9=3,"75",IF(J9=4,"87.5",IF(J9=5,"100",IF(J9=6,"112.50",IF(J9=7,"125",IF(J9=8,"137.50",0)))))))) | AD9: =IF(J9=9,"150",IF(J9=10,"162.50",IF(J9=11,"175",IF(J9=12,"187.50",IF(J9=13,"200",IF(J9=14,"212.5",IF(J9=15,"225",IF(J9=16,"237.5",0)))))))) | AE9: =IF(J9=17,"250",IF(J9=18,"262.50",IF(J9=19,"275",IF(J9=20,"287.50",IF(J9=21,"300",IF(J9=22,"312.50",0)))))) | AF9: =IF(I9=0,"0",IF(I9<=4999.99,"1",IF(I9<=5999.99,"2",IF(I9<=6999.99,"3",IF(I9<=7999.99,"4",IF(I9<=8999.99,"5",IF(I9<=9999.99,"6",IF(I9>=9999.99,"0",0)))))))) | AG9: =IF(I9<=9999.99,"0",IF(I9<=10999.99,"7",IF(I9<=11999.99,"8",IF(I9<=12999.99,"9",IF(I9<=13999.99,"10",IF(I9<=14999.99,"11",IF(I9>=14999.99,"0"))))))) | AH9: =IF(I9<=14999.99,"0",IF(I9<=15999.99,"12",IF(I9<=16999.99,"13",IF(I9<=17999.99,"14",IF(I9<=18999.99,"15",IF(I9<=19999.99,"16",IF(I9<=20999.99,"17",IF(I9>=20999.99,"0")))))))) | AI9: =IF(I9<=20999.99,"0",IF(I9<=21999.99,"18",IF(I9<=22999.99,"19",IF(I9<=23999.99,"20",IF(I9<=24999.99,"21",IF(I9<=25999.99,"22",IF(I9<=26999.99,"23",IF(I9>=26999.99,"0")))))))) | AJ9: =IF(I9<=26999.99,"0",IF(I9<=27999.99,"24",IF(I9<=28999.99,"25",IF(I9<=29999.99,"26",IF(I9>=30000,"27"))))) | AK9: =IF(J9=1,"50",IF(J9=2,"62.50",IF(J9=3,"75",IF(J9=4,"87.5",IF(J9=5,"100",IF(J9=6,"112.50",IF(J9=7,"125",IF(J9=8,"137.50",0)))))))) | AL9: =IF(J9=9,"150",IF(J9=10,"162.50",IF(J9=11,"175",IF(J9=12,"187.50",IF(J9=13,"200",IF(J9=14,"212.5",IF(J9=15,"225",IF(J9=16,"237.5",0)))))))) | AM9: =IF(J9=17,"250",IF(J9=18,"262.50",IF(J9=19,"275",IF(J9=20,"287.50",IF(J9=21,"300",IF(J9=22,"312.50",IF(J9=23,"325",IF(J9=24,"337.50",0)))))))) | AN9: =IF(J9=25,"350",IF(J9=26,"362.50",IF(J9=27,"375",0))) | AO9: =IF(I9=0,"0",IF(I9<=7999.99,"1",IF(I9<=8999.99,"2",IF(I9<=9999.99,"3",IF(I9<=10999.99,"4",IF(I9<=11999.99,"5",IF(I9<=12999.99,"6",IF(I9>=12999.99,"0",0)))))))) | AP9: =IF(I9<=12999.99,"0",IF(I9<=13999.99,"7",IF(I9<=14999.99,"8",IF(I9<=15999.99,"9",IF(I9<=16999.99,"10",IF(I9<=17999.99,"11",IF(I9>=17999.99,"0"))))))) | AQ9: =IF(I9<=17999.99,"0",IF(I9<=18999.99,"12",IF(I9<=19999.99,"13",IF(I9<=20999.99,"14",IF(I9<=21999.99,"15",IF(I9<=22999.99,"16",IF(I9<=23999.99,"17",IF(I9>=23999.99,"0")))))))) | AR9: =IF(I9<=23999.99,"0",IF(I9<=24999.99,"18",IF(I9<=25999.99,"19",IF(I9<=26999.99,"20",IF(I9<=27999.99,"21",IF(I9<=28999.99,"22",IF(I9<=29999.99,"23",IF(I9>=29999.99,"0")))))))) | AS9: =IF(I9<=29999.99,"0",IF(I9<=30999.99,"24",IF(I9<=31999.99,"25",IF(I9<=32999.99,"26",IF(I9<=33999.99,"27",IF(I9<=34999.99,"28",IF(I9>=35000,"29"))))))) | AT9: =IF(J9=1,"87.50",IF(J9=2,"100",IF(J9=3,"112.50",IF(J9=4,"125",IF(J9=5,"137.50",IF(J9=6,"150",IF(J9=7,"162.50",IF(J9=8,"175",0)))))))) | AU9: =IF(J9=9,"187.50",IF(J9=10,"200",IF(J9=11,"212.50",IF(J9=12,"225",IF(J9=13,"237.50",IF(J9=14,"250",IF(J9=15,"262.50",IF(J9=16,"275",0)))))))) | AV9: =IF(J9=17,"287.50",IF(J9=18,"300",IF(J9=19,"312.50",IF(J9=20,"325",IF(J9=21,"337.50",IF(J9=22,"350",IF(J9=23,"362.50",IF(J9=24,"375",0)))))))) | AW9: =IF(J9=25,"387.50",IF(J9=26,"400",IF(J9=27,"412.50",IF(J9=28,"425",IF(J9=29,"437.50",0))))) | AX9: =IF(I9=0,"0",IF(I9<=8999.99,"1",IF(I9<=9999.99,"2",IF(I9<=10999.99,"3",IF(I9<=11999.99,"4",IF(I9<=12999.99,"5",IF(I9<=13999.99,"6",IF(I9>=13999.99,"0",0)))))))) | AY9: =IF(I9<=13999.99,"0",IF(I9<=14999.99,"7",IF(I9<=15999.99,"8",IF(I9<=16999.99,"9",IF(I9<=17999.99,"10",IF(I9<=18999.99,"11",IF(I9>=18999.99,"0"))))))) | AZ9: =IF(I9<=18999.99,"0",IF(I9<=19999.99,"12",IF(I9<=20999.99,"13",IF(I9<=21999.99,"14",IF(I9<=22999.99,"15",IF(I9<=23999.99,"16",IF(I9<=24999.99,"17",IF(I9>=24999.99,"0")))))))) | BA9: =IF(I9<=24999.99,"0",IF(I9<=25999.99,"18",IF(I9<=26999.99,"19",IF(I9<=27999.99,"20",IF(I9<=28999.99,"21",IF(I9<=29999.99,"22",IF(I9<=30999.99,"23",IF(I9>=30999.99,"0")))))))) | BB9: =IF(I9<=30999.99,"0",IF(I9<=31999.99,"24",IF(I9<=32999.99,"25",IF(I9<=33999.99,"26",IF(I9<=34999.99,"27",IF(I9>=35000,"28")))))) | BC9: =IF(J9=1,"100",IF(J9=2,"112.50",IF(J9=3,"125",IF(J9=4,"137.50",IF(J9=5,"150",IF(J9=6,"162.50",IF(J9=7,"175",IF(J9=8,"187.50",0)))))))) | BD9: =IF(J9=9,"200",IF(J9=10,"212.50",IF(J9=11,"225",IF(J9=12,"237.50",IF(J9=13,"250",IF(J9=14,"262.50",IF(J9=15,"275",IF(J9=16,"287.50",0)))))))) | BE9: =IF(J9=17,"300",IF(J9=18,"312.50",IF(J9=19,"325",IF(J9=20,"337.50",IF(J9=21,"350",IF(J9=22,"362.50",IF(J9=23,"375",IF(J9=24,"387.50",0)))))))) | BF9: =IF(J9=25,"400",IF(J9=26,"412.50",IF(J9=27,"425",IF(J9=28,"437.50",0)))) | BG9: =IF(L9=2008,AK9+AL9+AM9+AN9,IF(L9=2009,AK9+AL9+AM9+AN9,IF(L9=2010,AK9+AL9+AM9+AN9,IF(L9=2011,AK9+AL9+AM9+AN9,IF(L9=2012,AK9+AL9+AM9+AN9,IF(L9=2013,AT9+AU9+AV9+AW9,IF(L9=2014,BC9+BD9+BE9+BF9,IF(L9=2015,BC9+BD9+BE9+BF9)))))))) | BH9: =IF(L9=2008,AK9+AL9+AM9+AN9,IF(L9=2009,AK9+AL9+AM9+AN9,IF(L9=2010,AK9+AL9+AM9+AN9,IF(L9=2011,AK9+AL9+AM9+AN9,IF(L9=2012,AK9+AL9+AM9+AN9,IF(L9=2013,AT9+AU9+AV9+AW9,IF(L9=2014,BC9+BD9+BE9+BF9,IF(L9=2015,BC9+BD9+BE9+BF9)))))))) | BI9: =IF(BH9=0,0,IF(BH9<=M9,BH9,IF(BH9>=M9,M9))) | BJ9: =CODE(B9:B18) | BK9: =ISBLANK(E9) | BL9: =CODE(E9) | BM9: =CHAR(BL9) | BN9: =ISBLANK(F9) | BO9: =ISBLANK(BS9) | BP9: =ISBLANK(BT9) | BQ9: =ISBLANK(G9) | BR9: =TEXT(BT9,"MMDDYYYY")
A10: =A9+1 | J10: =IF(L10=2008,AF10+AG10+AH10+AI10+AJ10,IF(L10=2009,AF10+AG10+AH10+AI10+AJ10,IF(L10=2010,AF10+AG10+AH10+AI10+AJ10,IF(L10=2011,AF10+AG10+AH10+AI10+AJ10,IF(L10=2012,AF10+AG10+AH10+AI10+AJ10,IF(L10=2013,AO10+AP10+AQ10+AR10+AS10,IF(L10=2014,AX10+AY10+AZ10+BA10+BB10,IF(L10=2015,AX10+AY10+AZ10+BA10+BB10)))))))) | K10: =K9 | L10: =L9 | M10: =M9 | N10: =IF(I10=0,"0",IF(I10<=4999.99,"1",IF(I10<=5999.99,"2",IF(I10<=6999.99,"3",IF(I10<=7999.99,"4",IF(I10<=8999.99,"5",IF(I10<=9999.99,"6",IF(I10>=9999.99,"0",0)))))))) | O10: =IF(I10<=9999.99,"0",IF(I10<=10999.99,"7",IF(I10<=11999.99,"8",IF(I10<=12999.99,"9",IF(I10<=13999.99,"10",IF(I10<=14999.99,"11",IF(I10>=14999.99,"0"))))))) | P10: =IF(I10<=14999.99,"0",IF(I10>=15000,"12")) | Q10: =IF(J10=1,"50",IF(J10=2,"62.50",IF(J10=3,"75",IF(J10=4,"87.5",IF(J10=5,"100",IF(J10=6,"112.50",IF(J10=7,"125",IF(J10=8,"137.50",0)))))))) | R10: =IF(J10=9,"150",IF(J10=10,"162.50",IF(J10=11,"175",IF(J10=12,"187.50",0)))) | S10: =IF(I10=0,"0",IF(I10<=4999.99,"1",IF(I10<=5999.99,"2",IF(I10<=6999.99,"3",IF(I10<=7999.99,"4",IF(I10<=8999.99,"5",IF(I10<=9999.99,"6",IF(I10>=9999.99,"0",0)))))))) | T10: =IF(I10<=9999.99,"0",IF(I10<=10999.99,"7",IF(I10<=11999.99,"8",IF(I10<=12999.99,"9",IF(I10<=13999.99,"10",IF(I10<=14999.99,"11",IF(I10>=14999.99,"0"))))))) | U10: =IF(I10<=14999.99,"0",IF(I10<=15999.99,"12",IF(I10<=16999.99,"13",IF(I10<=17999.99,"14",IF(I10<=18999.99,"15",IF(I10<=19999.99,"16",IF(I10>=20000,"17"))))))) | V10: =IF(J10=1,"50",IF(J10=2,"62.50",IF(J10=3,"75",IF(J10=4,"87.5",IF(J10=5,"100",IF(J10=6,"112.50",IF(J10=7,"125",IF(J10=8,"137.50",0)))))))) | W10: =IF(J10=9,"150",IF(J10=10,"162.50",IF(J10=11,"175",IF(J10=12,"187.50",IF(J10=13,"200",IF(J10=14,"212.5",IF(J10=15,"225",IF(J10=16,"237.5",0)))))))) | X10: =IF(J10=17,"250",0) | Y10: =IF(I10=0,"0",IF(I10<=4999.99,"1",IF(I10<=5999.99,"2",IF(I10<=6999.99,"3",IF(I10<=7999.99,"4",IF(I10<=8999.99,"5",IF(I10<=9999.99,"6",IF(I10>=9999.99,"0",0)))))))) | Z10: =IF(I10<=9999.99,"0",IF(I10<=10999.99,"7",IF(I10<=11999.99,"8",IF(I10<=12999.99,"9",IF(I10<=13999.99,"10",IF(I10<=14999.99,"11",IF(I10>=14999.99,"0"))))))) | AA10: =IF(I10<=14999.99,"0",IF(I10<=15999.99,"12",IF(I10<=16999.99,"13",IF(I10<=17999.99,"14",IF(I10<=18999.99,"15",IF(I10<=19999.99,"16",IF(I10<=20999.99,"17",IF(I10>=20999.99,"0")))))))) | AB10: =IF(I10<=20999.99,"0",IF(I10<=21999.99,"18",IF(I10<=22999.99,"19",IF(I10<=23999.99,"20",IF(I10<=24999.99,"21",IF(I10>=25000,"22")))))) | AC10: =IF(J10=1,"50",IF(J10=2,"62.50",IF(J10=3,"75",IF(J10=4,"87.5",IF(J10=5,"100",IF(J10=6,"112.50",IF(J10=7,"125",IF(J10=8,"137.50",0)))))))) | AD10: =IF(J10=9,"150",IF(J10=10,"162.50",IF(J10=11,"175",IF(J10=12,"187.50",IF(J10=13,"200",IF(J10=14,"212.5",IF(J10=15,"225",IF(J10=16,"237.5",0)))))))) | AE10: =IF(J10=17,"250",IF(J10=18,"262.50",IF(J10=19,"275",IF(J10=20,"287.50",IF(J10=21,"300",IF(J10=22,"312.50",0)))))) | AF10: =IF(I10=0,"0",IF(I10<=4999.99,"1",IF(I10<=5999.99,"2",IF(I10<=6999.99,"3",IF(I10<=7999.99,"4",IF(I10<=8999.99,"5",IF(I10<=9999.99,"6",IF(I10>=9999.99,"0",0)))))))) | AG10: =IF(I10<=9999.99,"0",IF(I10<=10999.99,"7",IF(I10<=11999.99,"8",IF(I10<=12999.99,"9",IF(I10<=13999.99,"10",IF(I10<=14999.99,"11",IF(I10>=14999.99,"0"))))))) | AH10: =IF(I10<=14999.99,"0",IF(I10<=15999.99,"12",IF(I10<=16999.99,"13",IF(I10<=17999.99,"14",IF(I10<=18999.99,"15",IF(I10<=19999.99,"16",IF(I10<=20999.99,"17",IF(I10>=20999.99,"0")))))))) | AI10: =IF(I10<=20999.99,"0",IF(I10<=21999.99,"18",IF(I10<=22999.99,"19",IF(I10<=23999.99,"20",IF(I10<=24999.99,"21",IF(I10<=25999.99,"22",IF(I10<=26999.99,"23",IF(I10>=26999.99,"0")))))))) | AJ10: =IF(I10<=26999.99,"0",IF(I10<=27999.99,"24",IF(I10<=28999.99,"25",IF(I10<=29999.99,"26",IF(I10>=30000,"27"))))) | AK10: =IF(J10=1,"50",IF(J10=2,"62.50",IF(J10=3,"75",IF(J10=4,"87.5",IF(J10=5,"100",IF(J10=6,"112.50",IF(J10=7,"125",IF(J10=8,"137.50",0)))))))) | AL10: =IF(J10=9,"150",IF(J10=10,"162.50",IF(J10=11,"175",IF(J10=12,"187.50",IF(J10=13,"200",IF(J10=14,"212.5",IF(J10=15,"225",IF(J10=16,"237.5",0)))))))) | AM10: =IF(J10=17,"250",IF(J10=18,"262.50",IF(J10=19,"275",IF(J10=20,"287.50",IF(J10=21,"300",IF(J10=22,"312.50",IF(J10=23,"325",IF(J10=24,"337.50",0)))))))) | AN10: =IF(J10=25,"350",IF(J10=26,"362.50",IF(J10=27,"375",0))) | AO10: =IF(I10=0,"0",IF(I10<=7999.99,"1",IF(I10<=8999.99,"2",IF(I10<=9999.99,"3",IF(I10<=10999.99,"4",IF(I10<=11999.99,"5",IF(I10<=12999.99,"6",IF(I10>=12999.99,"0",0)))))))) | AP10: =IF(I10<=12999.99,"0",IF(I10<=13999.99,"7",IF(I10<=14999.99,"8",IF(I10<=15999.99,"9",IF(I10<=16999.99,"10",IF(I10<=17999.99,"11",IF(I10>=17999.99,"0"))))))) | AQ10: =IF(I10<=17999.99,"0",IF(I10<=18999.99,"12",IF(I10<=19999.99,"13",IF(I10<=20999.99,"14",IF(I10<=21999.99,"15",IF(I10<=22999.99,"16",IF(I10<=23999.99,"17",IF(I10>=23999.99,"0")))))))) | AR10: =IF(I10<=23999.99,"0",IF(I10<=24999.99,"18",IF(I10<=25999.99,"19",IF(I10<=26999.99,"20",IF(I10<=27999.99,"21",IF(I10<=28999.99,"22",IF(I10<=29999.99,"23",IF(I10>=29999.99,"0")))))))) | AS10: =IF(I10<=29999.99,"0",IF(I10<=30999.99,"24",IF(I10<=31999.99,"25",IF(I10<=32999.99,"26",IF(I10<=33999.99,"27",IF(I10<=34999.99,"28",IF(I10>=35000,"29"))))))) | AT10: =IF(J10=1,"87.50",IF(J10=2,"100",IF(J10=3,"112.50",IF(J10=4,"125",IF(J10=5,"137.50",IF(J10=6,"150",IF(J10=7,"162.50",IF(J10=8,"175",0)))))))) | AU10: =IF(J10=9,"187.50",IF(J10=10,"200",IF(J10=11,"212.50",IF(J10=12,"225",IF(J10=13,"237.50",IF(J10=14,"250",IF(J10=15,"262.50",IF(J10=16,"275",0)))))))) | AV10: =IF(J10=17,"287.50",IF(J10=18,"300",IF(J10=19,"312.50",IF(J10=20,"325",IF(J10=21,"337.50",IF(J10=22,"350",IF(J10=23,"362.50",IF(J10=24,"375",0)))))))) | AW10: =IF(J10=25,"387.50",IF(J10=26,"400",IF(J10=27,"412.50",IF(J10=28,"425",IF(J10=29,"437.50",0))))) | AX10: =IF(I10=0,"0",IF(I10<=8999.99,"1",IF(I10<=9999.99,"2",IF(I10<=10999.99,"3",IF(I10<=11999.99,"4",IF(I10<=12999.99,"5",IF(I10<=13999.99,"6",IF(I10>=13999.99,"0",0)))))))) | AY10: =IF(I10<=13999.99,"0",IF(I10<=14999.99,"7",IF(I10<=15999.99,"8",IF(I10<=16999.99,"9",IF(I10<=17999.99,"10",IF(I10<=18999.99,"11",IF(I10>=18999.99,"0"))))))) | AZ10: =IF(I10<=18999.99,"0",IF(I10<=19999.99,"12",IF(I10<=20999.99,"13",IF(I10<=21999.99,"14",IF(I10<=22999.99,"15",IF(I10<=23999.99,"16",IF(I10<=24999.99,"17",IF(I10>=24999.99,"0")))))))) | BA10: =IF(I10<=24999.99,"0",IF(I10<=25999.99,"18",IF(I10<=26999.99,"19",IF(I10<=27999.99,"20",IF(I10<=28999.99,"21",IF(I10<=29999.99,"22",IF(I10<=30999.99,"23",IF(I10>=30999.99,"0")))))))) | BB10: =IF(I10<=30999.99,"0",IF(I10<=31999.99,"24",IF(I10<=32999.99,"25",IF(I10<=33999.99,"26",IF(I10<=34999.99,"27",IF(I10>=35000,"28")))))) | BC10: =IF(J10=1,"100",IF(J10=2,"112.50",IF(J10=3,"125",IF(J10=4,"137.50",IF(J10=5,"150",IF(J10=6,"162.50",IF(J10=7,"175",IF(J10=8,"187.50",0)))))))) | BD10: =IF(J10=9,"200",IF(J10=10,"212.50",IF(J10=11,"225",IF(J10=12,"237.50",IF(J10=13,"250",IF(J10=14,"262.50",IF(J10=15,"275",IF(J10=16,"287.50",0)))))))) | BE10: =IF(J10=17,"300",IF(J10=18,"312.50",IF(J10=19,"325",IF(J10=20,"337.50",IF(J10=21,"350",IF(J10=22,"362.50",IF(J10=23,"375",IF(J10=24,"387.50",0)))))))) | BF10: =IF(J10=25,"400",IF(J10=26,"412.50",IF(J10=27,"425",IF(J10=28,"437.50",0)))) | BG10: =IF(L10=2008,AK10+AL10+AM10+AN10,IF(L10=2009,AK10+AL10+AM10+AN10,IF(L10=2010,AK10+AL10+AM10+AN10,IF(L10=2011,AK10+AL10+AM10+AN10,IF(L10=2012,AK10+AL10+AM10+AN10,IF(L10=2013,AT10+AU10+AV10+AW10,IF(L10=2014,BC10+BD10+BE10+BF10,IF(L10=2015,BC10+BD10+BE10+BF10)))))))) | BH10: =IF(L10=2008,AK10+AL10+AM10+AN10,IF(L10=2009,AK10+AL10+AM10+AN10,IF(L10=2010,AK10+AL10+AM10+AN10,IF(L10=2011,AK10+AL10+AM10+AN10,IF(L10=2012,AK10+AL10+AM10+AN10,IF(L10=2013,AT10+AU10+AV10+AW10,IF(L10=2014,BC10+BD10+BE10+BF10,IF(L10=2015,BC10+BD10+BE10+BF10)))))))) | BI10: =IF(BH10=0,0,IF(BH10<=M10,BH10,IF(BH10>=M10,M10))) | BJ10: =CODE(B10:B19) | BK10: =ISBLANK(E10) | BL10: =CODE(E10) | BM10: =CHAR(BL10) | BN10: =ISBLANK(F10) | BO10: =ISBLANK(BS10) | BP10: =ISBLANK(BT10) | BQ10: =ISBLANK(G10) | BR10: =TEXT(BT10,"MMDDYYYY")
A11: =A10+1 | J11: =IF(L11=2008,AF11+AG11+AH11+AI11+AJ11,IF(L11=2009,AF11+AG11+AH11+AI11+AJ11,IF(L11=2010,AF11+AG11+AH11+AI11+AJ11,IF(L11=2011,AF11+AG11+AH11+AI11+AJ11,IF(L11=2012,AF11+AG11+AH11+AI11+AJ11,IF(L11=2013,AO11+AP11+AQ11+AR11+AS11,IF(L11=2014,AX11+AY11+AZ11+BA11+BB11,IF(L11=2015,AX11+AY11+AZ11+BA11+BB11)))))))) | K11: =K10 | L11: =L10 | M11: =M10 | N11: =IF(I11=0,"0",IF(I11<=4999.99,"1",IF(I11<=5999.99,"2",IF(I11<=6999.99,"3",IF(I11<=7999.99,"4",IF(I11<=8999.99,"5",IF(I11<=9999.99,"6",IF(I11>=9999.99,"0",0)))))))) | O11: =IF(I11<=9999.99,"0",IF(I11<=10999.99,"7",IF(I11<=11999.99,"8",IF(I11<=12999.99,"9",IF(I11<=13999.99,"10",IF(I11<=14999.99,"11",IF(I11>=14999.99,"0"))))))) | P11: =IF(I11<=14999.99,"0",IF(I11>=15000,"12")) | Q11: =IF(J11=1,"50",IF(J11=2,"62.50",IF(J11=3,"75",IF(J11=4,"87.5",IF(J11=5,"100",IF(J11=6,"112.50",IF(J11=7,"125",IF(J11=8,"137.50",0)))))))) | R11: =IF(J11=9,"150",IF(J11=10,"162.50",IF(J11=11,"175",IF(J11=12,"187.50",0)))) | S11: =IF(I11=0,"0",IF(I11<=4999.99,"1",IF(I11<=5999.99,"2",IF(I11<=6999.99,"3",IF(I11<=7999.99,"4",IF(I11<=8999.99,"5",IF(I11<=9999.99,"6",IF(I11>=9999.99,"0",0)))))))) | T11: =IF(I11<=9999.99,"0",IF(I11<=10999.99,"7",IF(I11<=11999.99,"8",IF(I11<=12999.99,"9",IF(I11<=13999.99,"10",IF(I11<=14999.99,"11",IF(I11>=14999.99,"0"))))))) | U11: =IF(I11<=14999.99,"0",IF(I11<=15999.99,"12",IF(I11<=16999.99,"13",IF(I11<=17999.99,"14",IF(I11<=18999.99,"15",IF(I11<=19999.99,"16",IF(I11>=20000,"17"))))))) | V11: =IF(J11=1,"50",IF(J11=2,"62.50",IF(J11=3,"75",IF(J11=4,"87.5",IF(J11=5,"100",IF(J11=6,"112.50",IF(J11=7,"125",IF(J11=8,"137.50",0)))))))) | W11: =IF(J11=9,"150",IF(J11=10,"162.50",IF(J11=11,"175",IF(J11=12,"187.50",IF(J11=13,"200",IF(J11=14,"212.5",IF(J11=15,"225",IF(J11=16,"237.5",0)))))))) | X11: =IF(J11=17,"250",0) | Y11: =IF(I11=0,"0",IF(I11<=4999.99,"1",IF(I11<=5999.99,"2",IF(I11<=6999.99,"3",IF(I11<=7999.99,"4",IF(I11<=8999.99,"5",IF(I11<=9999.99,"6",IF(I11>=9999.99,"0",0)))))))) | Z11: =IF(I11<=9999.99,"0",IF(I11<=10999.99,"7",IF(I11<=11999.99,"8",IF(I11<=12999.99,"9",IF(I11<=13999.99,"10",IF(I11<=14999.99,"11",IF(I11>=14999.99,"0"))))))) | AA11: =IF(I11<=14999.99,"0",IF(I11<=15999.99,"12",IF(I11<=16999.99,"13",IF(I11<=17999.99,"14",IF(I11<=18999.99,"15",IF(I11<=19999.99,"16",IF(I11<=20999.99,"17",IF(I11>=20999.99,"0")))))))) | AB11: =IF(I11<=20999.99,"0",IF(I11<=21999.99,"18",IF(I11<=22999.99,"19",IF(I11<=23999.99,"20",IF(I11<=24999.99,"21",IF(I11>=25000,"22")))))) | AC11: =IF(J11=1,"50",IF(J11=2,"62.50",IF(J11=3,"75",IF(J11=4,"87.5",IF(J11=5,"100",IF(J11=6,"112.50",IF(J11=7,"125",IF(J11=8,"137.50",0)))))))) | AD11: =IF(J11=9,"150",IF(J11=10,"162.50",IF(J11=11,"175",IF(J11=12,"187.50",IF(J11=13,"200",IF(J11=14,"212.5",IF(J11=15,"225",IF(J11=16,"237.5",0)))))))) | AE11: =IF(J11=17,"250",IF(J11=18,"262.50",IF(J11=19,"275",IF(J11=20,"287.50",IF(J11=21,"300",IF(J11=22,"312.50",0)))))) | AF11: =IF(I11=0,"0",IF(I11<=4999.99,"1",IF(I11<=5999.99,"2",IF(I11<=6999.99,"3",IF(I11<=7999.99,"4",IF(I11<=8999.99,"5",IF(I11<=9999.99,"6",IF(I11>=9999.99,"0",0)))))))) | AG11: =IF(I11<=9999.99,"0",IF(I11<=10999.99,"7",IF(I11<=11999.99,"8",IF(I11<=12999.99,"9",IF(I11<=13999.99,"10",IF(I11<=14999.99,"11",IF(I11>=14999.99,"0"))))))) | AH11: =IF(I11<=14999.99,"0",IF(I11<=15999.99,"12",IF(I11<=16999.99,"13",IF(I11<=17999.99,"14",IF(I11<=18999.99,"15",IF(I11<=19999.99,"16",IF(I11<=20999.99,"17",IF(I11>=20999.99,"0")))))))) | AI11: =IF(I11<=20999.99,"0",IF(I11<=21999.99,"18",IF(I11<=22999.99,"19",IF(I11<=23999.99,"20",IF(I11<=24999.99,"21",IF(I11<=25999.99,"22",IF(I11<=26999.99,"23",IF(I11>=26999.99,"0")))))))) | AJ11: =IF(I11<=26999.99,"0",IF(I11<=27999.99,"24",IF(I11<=28999.99,"25",IF(I11<=29999.99,"26",IF(I11>=30000,"27"))))) | AK11: =IF(J11=1,"50",IF(J11=2,"62.50",IF(J11=3,"75",IF(J11=4,"87.5",IF(J11=5,"100",IF(J11=6,"112.50",IF(J11=7,"125",IF(J11=8,"137.50",0)))))))) | AL11: =IF(J11=9,"150",IF(J11=10,"162.50",IF(J11=11,"175",IF(J11=12,"187.50",IF(J11=13,"200",IF(J11=14,"212.5",IF(J11=15,"225",IF(J11=16,"237.5",0)))))))) | AM11: =IF(J11=17,"250",IF(J11=18,"262.50",IF(J11=19,"275",IF(J11=20,"287.50",IF(J11=21,"300",IF(J11=22,"312.50",IF(J11=23,"325",IF(J11=24,"337.50",0)))))))) | AN11: =IF(J11=25,"350",IF(J11=26,"362.50",IF(J11=27,"375",0))) | AO11: =IF(I11=0,"0",IF(I11<=7999.99,"1",IF(I11<=8999.99,"2",IF(I11<=9999.99,"3",IF(I11<=10999.99,"4",IF(I11<=11999.99,"5",IF(I11<=12999.99,"6",IF(I11>=12999.99,"0",0)))))))) | AP11: =IF(I11<=12999.99,"0",IF(I11<=13999.99,"7",IF(I11<=14999.99,"8",IF(I11<=15999.99,"9",IF(I11<=16999.99,"10",IF(I11<=17999.99,"11",IF(I11>=17999.99,"0"))))))) | AQ11: =IF(I11<=17999.99,"0",IF(I11<=18999.99,"12",IF(I11<=19999.99,"13",IF(I11<=20999.99,"14",IF(I11<=21999.99,"15",IF(I11<=22999.99,"16",IF(I11<=23999.99,"17",IF(I11>=23999.99,"0")))))))) | AR11: =IF(I11<=23999.99,"0",IF(I11<=24999.99,"18",IF(I11<=25999.99,"19",IF(I11<=26999.99,"20",IF(I11<=27999.99,"21",IF(I11<=28999.99,"22",IF(I11<=29999.99,"23",IF(I11>=29999.99,"0")))))))) | AS11: =IF(I11<=29999.99,"0",IF(I11<=30999.99,"24",IF(I11<=31999.99,"25",IF(I11<=32999.99,"26",IF(I11<=33999.99,"27",IF(I11<=34999.99,"28",IF(I11>=35000,"29"))))))) | AT11: =IF(J11=1,"87.50",IF(J11=2,"100",IF(J11=3,"112.50",IF(J11=4,"125",IF(J11=5,"137.50",IF(J11=6,"150",IF(J11=7,"162.50",IF(J11=8,"175",0)))))))) | AU11: =IF(J11=9,"187.50",IF(J11=10,"200",IF(J11=11,"212.50",IF(J11=12,"225",IF(J11=13,"237.50",IF(J11=14,"250",IF(J11=15,"262.50",IF(J11=16,"275",0)))))))) | AV11: =IF(J11=17,"287.50",IF(J11=18,"300",IF(J11=19,"312.50",IF(J11=20,"325",IF(J11=21,"337.50",IF(J11=22,"350",IF(J11=23,"362.50",IF(J11=24,"375",0)))))))) | AW11: =IF(J11=25,"387.50",IF(J11=26,"400",IF(J11=27,"412.50",IF(J11=28,"425",IF(J11=29,"437.50",0))))) | AX11: =IF(I11=0,"0",IF(I11<=8999.99,"1",IF(I11<=9999.99,"2",IF(I11<=10999.99,"3",IF(I11<=11999.99,"4",IF(I11<=12999.99,"5",IF(I11<=13999.99,"6",IF(I11>=13999.99,"0",0)))))))) | AY11: =IF(I11<=13999.99,"0",IF(I11<=14999.99,"7",IF(I11<=15999.99,"8",IF(I11<=16999.99,"9",IF(I11<=17999.99,"10",IF(I11<=18999.99,"11",IF(I11>=18999.99,"0"))))))) | AZ11: =IF(I11<=18999.99,"0",IF(I11<=19999.99,"12",IF(I11<=20999.99,"13",IF(I11<=21999.99,"14",IF(I11<=22999.99,"15",IF(I11<=23999.99,"16",IF(I11<=24999.99,"17",IF(I11>=24999.99,"0")))))))) | BA11: =IF(I11<=24999.99,"0",IF(I11<=25999.99,"18",IF(I11<=26999.99,"19",IF(I11<=27999.99,"20",IF(I11<=28999.99,"21",IF(I11<=29999.99,"22",IF(I11<=30999.99,"23",IF(I11>=30999.99,"0")))))))) | BB11: =IF(I11<=30999.99,"0",IF(I11<=31999.99,"24",IF(I11<=32999.99,"25",IF(I11<=33999.99,"26",IF(I11<=34999.99,"27",IF(I11>=35000,"28")))))) | BC11: =IF(J11=1,"100",IF(J11=2,"112.50",IF(J11=3,"125",IF(J11=4,"137.50",IF(J11=5,"150",IF(J11=6,"162.50",IF(J11=7,"175",IF(J11=8,"187.50",0)))))))) | BD11: =IF(J11=9,"200",IF(J11=10,"212.50",IF(J11=11,"225",IF(J11=12,"237.50",IF(J11=13,"250",IF(J11=14,"262.50",IF(J11=15,"275",IF(J11=16,"287.50",0)))))))) | BE11: =IF(J11=17,"300",IF(J11=18,"312.50",IF(J11=19,"325",IF(J11=20,"337.50",IF(J11=21,"350",IF(J11=22,"362.50",IF(J11=23,"375",IF(J11=24,"387.50",0)))))))) | BF11: =IF(J11=25,"400",IF(J11=26,"412.50",IF(J11=27,"425",IF(J11=28,"437.50",0)))) | BG11: =IF(L11=2008,AK11+AL11+AM11+AN11,IF(L11=2009,AK11+AL11+AM11+AN11,IF(L11=2010,AK11+AL11+AM11+AN11,IF(L11=2011,AK11+AL11+AM11+AN11,IF(L11=2012,AK11+AL11+AM11+AN11,IF(L11=2013,AT11+AU11+AV11+AW11,IF(L11=2014,BC11+BD11+BE11+BF11,IF(L11=2015,BC11+BD11+BE11+BF11)))))))) | BH11: =IF(L11=2008,AK11+AL11+AM11+AN11,IF(L11=2009,AK11+AL11+AM11+AN11,IF(L11=2010,AK11+AL11+AM11+AN11,IF(L11=2011,AK11+AL11+AM11+AN11,IF(L11=2012,AK11+AL11+AM11+AN11,IF(L11=2013,AT11+AU11+AV11+AW11,IF(L11=2014,BC11+BD11+BE11+BF11,IF(L11=2015,BC11+BD11+BE11+BF11)))))))) | BI11: =IF(BH11=0,0,IF(BH11<=M11,BH11,IF(BH11>=M11,M11))) | BJ11: =CODE(B11:B20) | BK11: =ISBLANK(E11) | BL11: =CODE(E11) | BM11: =CHAR(BL11) | BN11: =ISBLANK(F11) | BO11: =ISBLANK(BS11) | BP11: =ISBLANK(BT11) | BQ11: =ISBLANK(G11) | BR11: =TEXT(BT11,"MMDDYYYY")
A12: =A11+1 | J12: =IF(L12=2008,AF12+AG12+AH12+AI12+AJ12,IF(L12=2009,AF12+AG12+AH12+AI12+AJ12,IF(L12=2010,AF12+AG12+AH12+AI12+AJ12,IF(L12=2011,AF12+AG12+AH12+AI12+AJ12,IF(L12=2012,AF12+AG12+AH12+AI12+AJ12,IF(L12=2013,AO12+AP12+AQ12+AR12+AS12,IF(L12=2014,AX12+AY12+AZ12+BA12+BB12,IF(L12=2015,AX12+AY12+AZ12+BA12+BB12)))))))) | K12: =K11 | L12: =L11 | M12: =M11 | N12: =IF(I12=0,"0",IF(I12<=4999.99,"1",IF(I12<=5999.99,"2",IF(I12<=6999.99,"3",IF(I12<=7999.99,"4",IF(I12<=8999.99,"5",IF(I12<=9999.99,"6",IF(I12>=9999.99,"0",0)))))))) | O12: =IF(I12<=9999.99,"0",IF(I12<=10999.99,"7",IF(I12<=11999.99,"8",IF(I12<=12999.99,"9",IF(I12<=13999.99,"10",IF(I12<=14999.99,"11",IF(I12>=14999.99,"0"))))))) | P12: =IF(I12<=14999.99,"0",IF(I12>=15000,"12")) | Q12: =IF(J12=1,"50",IF(J12=2,"62.50",IF(J12=3,"75",IF(J12=4,"87.5",IF(J12=5,"100",IF(J12=6,"112.50",IF(J12=7,"125",IF(J12=8,"137.50",0)))))))) | R12: =IF(J12=9,"150",IF(J12=10,"162.50",IF(J12=11,"175",IF(J12=12,"187.50",0)))) | S12: =IF(I12=0,"0",IF(I12<=4999.99,"1",IF(I12<=5999.99,"2",IF(I12<=6999.99,"3",IF(I12<=7999.99,"4",IF(I12<=8999.99,"5",IF(I12<=9999.99,"6",IF(I12>=9999.99,"0",0)))))))) | T12: =IF(I12<=9999.99,"0",IF(I12<=10999.99,"7",IF(I12<=11999.99,"8",IF(I12<=12999.99,"9",IF(I12<=13999.99,"10",IF(I12<=14999.99,"11",IF(I12>=14999.99,"0"))))))) | U12: =IF(I12<=14999.99,"0",IF(I12<=15999.99,"12",IF(I12<=16999.99,"13",IF(I12<=17999.99,"14",IF(I12<=18999.99,"15",IF(I12<=19999.99,"16",IF(I12>=20000,"17"))))))) | V12: =IF(J12=1,"50",IF(J12=2,"62.50",IF(J12=3,"75",IF(J12=4,"87.5",IF(J12=5,"100",IF(J12=6,"112.50",IF(J12=7,"125",IF(J12=8,"137.50",0)))))))) | W12: =IF(J12=9,"150",IF(J12=10,"162.50",IF(J12=11,"175",IF(J12=12,"187.50",IF(J12=13,"200",IF(J12=14,"212.5",IF(J12=15,"225",IF(J12=16,"237.5",0)))))))) | X12: =IF(J12=17,"250",0) | Y12: =IF(I12=0,"0",IF(I12<=4999.99,"1",IF(I12<=5999.99,"2",IF(I12<=6999.99,"3",IF(I12<=7999.99,"4",IF(I12<=8999.99,"5",IF(I12<=9999.99,"6",IF(I12>=9999.99,"0",0)))))))) | Z12: =IF(I12<=9999.99,"0",IF(I12<=10999.99,"7",IF(I12<=11999.99,"8",IF(I12<=12999.99,"9",IF(I12<=13999.99,"10",IF(I12<=14999.99,"11",IF(I12>=14999.99,"0"))))))) | AA12: =IF(I12<=14999.99,"0",IF(I12<=15999.99,"12",IF(I12<=16999.99,"13",IF(I12<=17999.99,"14",IF(I12<=18999.99,"15",IF(I12<=19999.99,"16",IF(I12<=20999.99,"17",IF(I12>=20999.99,"0")))))))) | AB12: =IF(I12<=20999.99,"0",IF(I12<=21999.99,"18",IF(I12<=22999.99,"19",IF(I12<=23999.99,"20",IF(I12<=24999.99,"21",IF(I12>=25000,"22")))))) | AC12: =IF(J12=1,"50",IF(J12=2,"62.50",IF(J12=3,"75",IF(J12=4,"87.5",IF(J12=5,"100",IF(J12=6,"112.50",IF(J12=7,"125",IF(J12=8,"137.50",0)))))))) | AD12: =IF(J12=9,"150",IF(J12=10,"162.50",IF(J12=11,"175",IF(J12=12,"187.50",IF(J12=13,"200",IF(J12=14,"212.5",IF(J12=15,"225",IF(J12=16,"237.5",0)))))))) | AE12: =IF(J12=17,"250",IF(J12=18,"262.50",IF(J12=19,"275",IF(J12=20,"287.50",IF(J12=21,"300",IF(J12=22,"312.50",0)))))) | AF12: =IF(I12=0,"0",IF(I12<=4999.99,"1",IF(I12<=5999.99,"2",IF(I12<=6999.99,"3",IF(I12<=7999.99,"4",IF(I12<=8999.99,"5",IF(I12<=9999.99,"6",IF(I12>=9999.99,"0",0)))))))) | AG12: =IF(I12<=9999.99,"0",IF(I12<=10999.99,"7",IF(I12<=11999.99,"8",IF(I12<=12999.99,"9",IF(I12<=13999.99,"10",IF(I12<=14999.99,"11",IF(I12>=14999.99,"0"))))))) | AH12: =IF(I12<=14999.99,"0",IF(I12<=15999.99,"12",IF(I12<=16999.99,"13",IF(I12<=17999.99,"14",IF(I12<=18999.99,"15",IF(I12<=19999.99,"16",IF(I12<=20999.99,"17",IF(I12>=20999.99,"0")))))))) | AI12: =IF(I12<=20999.99,"0",IF(I12<=21999.99,"18",IF(I12<=22999.99,"19",IF(I12<=23999.99,"20",IF(I12<=24999.99,"21",IF(I12<=25999.99,"22",IF(I12<=26999.99,"23",IF(I12>=26999.99,"0")))))))) | AJ12: =IF(I12<=26999.99,"0",IF(I12<=27999.99,"24",IF(I12<=28999.99,"25",IF(I12<=29999.99,"26",IF(I12>=30000,"27"))))) | AK12: =IF(J12=1,"50",IF(J12=2,"62.50",IF(J12=3,"75",IF(J12=4,"87.5",IF(J12=5,"100",IF(J12=6,"112.50",IF(J12=7,"125",IF(J12=8,"137.50",0)))))))) | AL12: =IF(J12=9,"150",IF(J12=10,"162.50",IF(J12=11,"175",IF(J12=12,"187.50",IF(J12=13,"200",IF(J12=14,"212.5",IF(J12=15,"225",IF(J12=16,"237.5",0)))))))) | AM12: =IF(J12=17,"250",IF(J12=18,"262.50",IF(J12=19,"275",IF(J12=20,"287.50",IF(J12=21,"300",IF(J12=22,"312.50",IF(J12=23,"325",IF(J12=24,"337.50",0)))))))) | AN12: =IF(J12=25,"350",IF(J12=26,"362.50",IF(J12=27,"375",0))) | AO12: =IF(I12=0,"0",IF(I12<=7999.99,"1",IF(I12<=8999.99,"2",IF(I12<=9999.99,"3",IF(I12<=10999.99,"4",IF(I12<=11999.99,"5",IF(I12<=12999.99,"6",IF(I12>=12999.99,"0",0)))))))) | AP12: =IF(I12<=12999.99,"0",IF(I12<=13999.99,"7",IF(I12<=14999.99,"8",IF(I12<=15999.99,"9",IF(I12<=16999.99,"10",IF(I12<=17999.99,"11",IF(I12>=17999.99,"0"))))))) | AQ12: =IF(I12<=17999.99,"0",IF(I12<=18999.99,"12",IF(I12<=19999.99,"13",IF(I12<=20999.99,"14",IF(I12<=21999.99,"15",IF(I12<=22999.99,"16",IF(I12<=23999.99,"17",IF(I12>=23999.99,"0")))))))) | AR12: =IF(I12<=23999.99,"0",IF(I12<=24999.99,"18",IF(I12<=25999.99,"19",IF(I12<=26999.99,"20",IF(I12<=27999.99,"21",IF(I12<=28999.99,"22",IF(I12<=29999.99,"23",IF(I12>=29999.99,"0")))))))) | AS12: =IF(I12<=29999.99,"0",IF(I12<=30999.99,"24",IF(I12<=31999.99,"25",IF(I12<=32999.99,"26",IF(I12<=33999.99,"27",IF(I12<=34999.99,"28",IF(I12>=35000,"29"))))))) | AT12: =IF(J12=1,"87.50",IF(J12=2,"100",IF(J12=3,"112.50",IF(J12=4,"125",IF(J12=5,"137.50",IF(J12=6,"150",IF(J12=7,"162.50",IF(J12=8,"175",0)))))))) | AU12: =IF(J12=9,"187.50",IF(J12=10,"200",IF(J12=11,"212.50",IF(J12=12,"225",IF(J12=13,"237.50",IF(J12=14,"250",IF(J12=15,"262.50",IF(J12=16,"275",0)))))))) | AV12: =IF(J12=17,"287.50",IF(J12=18,"300",IF(J12=19,"312.50",IF(J12=20,"325",IF(J12=21,"337.50",IF(J12=22,"350",IF(J12=23,"362.50",IF(J12=24,"375",0)))))))) | AW12: =IF(J12=25,"387.50",IF(J12=26,"400",IF(J12=27,"412.50",IF(J12=28,"425",IF(J12=29,"437.50",0))))) | AX12: =IF(I12=0,"0",IF(I12<=8999.99,"1",IF(I12<=9999.99,"2",IF(I12<=10999.99,"3",IF(I12<=11999.99,"4",IF(I12<=12999.99,"5",IF(I12<=13999.99,"6",IF(I12>=13999.99,"0",0)))))))) | AY12: =IF(I12<=13999.99,"0",IF(I12<=14999.99,"7",IF(I12<=15999.99,"8",IF(I12<=16999.99,"9",IF(I12<=17999.99,"10",IF(I12<=18999.99,"11",IF(I12>=18999.99,"0"))))))) | AZ12: =IF(I12<=18999.99,"0",IF(I12<=19999.99,"12",IF(I12<=20999.99,"13",IF(I12<=21999.99,"14",IF(I12<=22999.99,"15",IF(I12<=23999.99,"16",IF(I12<=24999.99,"17",IF(I12>=24999.99,"0")))))))) | BA12: =IF(I12<=24999.99,"0",IF(I12<=25999.99,"18",IF(I12<=26999.99,"19",IF(I12<=27999.99,"20",IF(I12<=28999.99,"21",IF(I12<=29999.99,"22",IF(I12<=30999.99,"23",IF(I12>=30999.99,"0")))))))) | BB12: =IF(I12<=30999.99,"0",IF(I12<=31999.99,"24",IF(I12<=32999.99,"25",IF(I12<=33999.99,"26",IF(I12<=34999.99,"27",IF(I12>=35000,"28")))))) | BC12: =IF(J12=1,"100",IF(J12=2,"112.50",IF(J12=3,"125",IF(J12=4,"137.50",IF(J12=5,"150",IF(J12=6,"162.50",IF(J12=7,"175",IF(J12=8,"187.50",0)))))))) | BD12: =IF(J12=9,"200",IF(J12=10,"212.50",IF(J12=11,"225",IF(J12=12,"237.50",IF(J12=13,"250",IF(J12=14,"262.50",IF(J12=15,"275",IF(J12=16,"287.50",0)))))))) | BE12: =IF(J12=17,"300",IF(J12=18,"312.50",IF(J12=19,"325",IF(J12=20,"337.50",IF(J12=21,"350",IF(J12=22,"362.50",IF(J12=23,"375",IF(J12=24,"387.50",0)))))))) | BF12: =IF(J12=25,"400",IF(J12=26,"412.50",IF(J12=27,"425",IF(J12=28,"437.50",0)))) | BG12: =IF(L12=2008,AK12+AL12+AM12+AN12,IF(L12=2009,AK12+AL12+AM12+AN12,IF(L12=2010,AK12+AL12+AM12+AN12,IF(L12=2011,AK12+AL12+AM12+AN12,IF(L12=2012,AK12+AL12+AM12+AN12,IF(L12=2013,AT12+AU12+AV12+AW12,IF(L12=2014,BC12+BD12+BE12+BF12,IF(L12=2015,BC12+BD12+BE12+BF12)))))))) | BH12: =IF(L12=2008,AK12+AL12+AM12+AN12,IF(L12=2009,AK12+AL12+AM12+AN12,IF(L12=2010,AK12+AL12+AM12+AN12,IF(L12=2011,AK12+AL12+AM12+AN12,IF(L12=2012,AK12+AL12+AM12+AN12,IF(L12=2013,AT12+AU12+AV12+AW12,IF(L12=2014,BC12+BD12+BE12+BF12,IF(L12=2015,BC12+BD12+BE12+BF12)))))))) | BI12: =IF(BH12=0,0,IF(BH12<=M12,BH12,IF(BH12>=M12,M12))) | BJ12: =CODE(B12:B20) | BK12: =ISBLANK(E12) | BL12: =CODE(E12) | BM12: =CHAR(BL12) | BN12: =ISBLANK(F12) | BO12: =ISBLANK(BS12) | BP12: =ISBLANK(BT12) | BQ12: =ISBLANK(G12) | BR12: =TEXT(BT12,"MMDDYYYY")
A13: =A12+1 | J13: =IF(L13=2008,AF13+AG13+AH13+AI13+AJ13,IF(L13=2009,AF13+AG13+AH13+AI13+AJ13,IF(L13=2010,AF13+AG13+AH13+AI13+AJ13,IF(L13=2011,AF13+AG13+AH13+AI13+AJ13,IF(L13=2012,AF13+AG13+AH13+AI13+AJ13,IF(L13=2013,AO13+AP13+AQ13+AR13+AS13,IF(L13=2014,AX13+AY13+AZ13+BA13+BB13,IF(L13=2015,AX13+AY13+AZ13+BA13+BB13)))))))) | K13: =K12 | L13: =L12 | M13: =M12 | N13: =IF(I13=0,"0",IF(I13<=4999.99,"1",IF(I13<=5999.99,"2",IF(I13<=6999.99,"3",IF(I13<=7999.99,"4",IF(I13<=8999.99,"5",IF(I13<=9999.99,"6",IF(I13>=9999.99,"0",0)))))))) | O13: =IF(I13<=9999.99,"0",IF(I13<=10999.99,"7",IF(I13<=11999.99,"8",IF(I13<=12999.99,"9",IF(I13<=13999.99,"10",IF(I13<=14999.99,"11",IF(I13>=14999.99,"0"))))))) | P13: =IF(I13<=14999.99,"0",IF(I13>=15000,"12")) | Q13: =IF(J13=1,"50",IF(J13=2,"62.50",IF(J13=3,"75",IF(J13=4,"87.5",IF(J13=5,"100",IF(J13=6,"112.50",IF(J13=7,"125",IF(J13=8,"137.50",0)))))))) | R13: =IF(J13=9,"150",IF(J13=10,"162.50",IF(J13=11,"175",IF(J13=12,"187.50",0)))) | S13: =IF(I13=0,"0",IF(I13<=4999.99,"1",IF(I13<=5999.99,"2",IF(I13<=6999.99,"3",IF(I13<=7999.99,"4",IF(I13<=8999.99,"5",IF(I13<=9999.99,"6",IF(I13>=9999.99,"0",0)))))))) | T13: =IF(I13<=9999.99,"0",IF(I13<=10999.99,"7",IF(I13<=11999.99,"8",IF(I13<=12999.99,"9",IF(I13<=13999.99,"10",IF(I13<=14999.99,"11",IF(I13>=14999.99,"0"))))))) | U13: =IF(I13<=14999.99,"0",IF(I13<=15999.99,"12",IF(I13<=16999.99,"13",IF(I13<=17999.99,"14",IF(I13<=18999.99,"15",IF(I13<=19999.99,"16",IF(I13>=20000,"17"))))))) | V13: =IF(J13=1,"50",IF(J13=2,"62.50",IF(J13=3,"75",IF(J13=4,"87.5",IF(J13=5,"100",IF(J13=6,"112.50",IF(J13=7,"125",IF(J13=8,"137.50",0)))))))) | W13: =IF(J13=9,"150",IF(J13=10,"162.50",IF(J13=11,"175",IF(J13=12,"187.50",IF(J13=13,"200",IF(J13=14,"212.5",IF(J13=15,"225",IF(J13=16,"237.5",0)))))))) | X13: =IF(J13=17,"250",0) | Y13: =IF(I13=0,"0",IF(I13<=4999.99,"1",IF(I13<=5999.99,"2",IF(I13<=6999.99,"3",IF(I13<=7999.99,"4",IF(I13<=8999.99,"5",IF(I13<=9999.99,"6",IF(I13>=9999.99,"0",0)))))))) | Z13: =IF(I13<=9999.99,"0",IF(I13<=10999.99,"7",IF(I13<=11999.99,"8",IF(I13<=12999.99,"9",IF(I13<=13999.99,"10",IF(I13<=14999.99,"11",IF(I13>=14999.99,"0"))))))) | AA13: =IF(I13<=14999.99,"0",IF(I13<=15999.99,"12",IF(I13<=16999.99,"13",IF(I13<=17999.99,"14",IF(I13<=18999.99,"15",IF(I13<=19999.99,"16",IF(I13<=20999.99,"17",IF(I13>=20999.99,"0")))))))) | AB13: =IF(I13<=20999.99,"0",IF(I13<=21999.99,"18",IF(I13<=22999.99,"19",IF(I13<=23999.99,"20",IF(I13<=24999.99,"21",IF(I13>=25000,"22")))))) | AC13: =IF(J13=1,"50",IF(J13=2,"62.50",IF(J13=3,"75",IF(J13=4,"87.5",IF(J13=5,"100",IF(J13=6,"112.50",IF(J13=7,"125",IF(J13=8,"137.50",0)))))))) | AD13: =IF(J13=9,"150",IF(J13=10,"162.50",IF(J13=11,"175",IF(J13=12,"187.50",IF(J13=13,"200",IF(J13=14,"212.5",IF(J13=15,"225",IF(J13=16,"237.5",0)))))))) | AE13: =IF(J13=17,"250",IF(J13=18,"262.50",IF(J13=19,"275",IF(J13=20,"287.50",IF(J13=21,"300",IF(J13=22,"312.50",0)))))) | AF13: =IF(I13=0,"0",IF(I13<=4999.99,"1",IF(I13<=5999.99,"2",IF(I13<=6999.99,"3",IF(I13<=7999.99,"4",IF(I13<=8999.99,"5",IF(I13<=9999.99,"6",IF(I13>=9999.99,"0",0)))))))) | AG13: =IF(I13<=9999.99,"0",IF(I13<=10999.99,"7",IF(I13<=11999.99,"8",IF(I13<=12999.99,"9",IF(I13<=13999.99,"10",IF(I13<=14999.99,"11",IF(I13>=14999.99,"0"))))))) | AH13: =IF(I13<=14999.99,"0",IF(I13<=15999.99,"12",IF(I13<=16999.99,"13",IF(I13<=17999.99,"14",IF(I13<=18999.99,"15",IF(I13<=19999.99,"16",IF(I13<=20999.99,"17",IF(I13>=20999.99,"0")))))))) | AI13: =IF(I13<=20999.99,"0",IF(I13<=21999.99,"18",IF(I13<=22999.99,"19",IF(I13<=23999.99,"20",IF(I13<=24999.99,"21",IF(I13<=25999.99,"22",IF(I13<=26999.99,"23",IF(I13>=26999.99,"0")))))))) | AJ13: =IF(I13<=26999.99,"0",IF(I13<=27999.99,"24",IF(I13<=28999.99,"25",IF(I13<=29999.99,"26",IF(I13>=30000,"27"))))) | AK13: =IF(J13=1,"50",IF(J13=2,"62.50",IF(J13=3,"75",IF(J13=4,"87.5",IF(J13=5,"100",IF(J13=6,"112.50",IF(J13=7,"125",IF(J13=8,"137.50",0)))))))) | AL13: =IF(J13=9,"150",IF(J13=10,"162.50",IF(J13=11,"175",IF(J13=12,"187.50",IF(J13=13,"200",IF(J13=14,"212.5",IF(J13=15,"225",IF(J13=16,"237.5",0)))))))) | AM13: =IF(J13=17,"250",IF(J13=18,"262.50",IF(J13=19,"275",IF(J13=20,"287.50",IF(J13=21,"300",IF(J13=22,"312.50",IF(J13=23,"325",IF(J13=24,"337.50",0)))))))) | AN13: =IF(J13=25,"350",IF(J13=26,"362.50",IF(J13=27,"375",0))) | AO13: =IF(I13=0,"0",IF(I13<=7999.99,"1",IF(I13<=8999.99,"2",IF(I13<=9999.99,"3",IF(I13<=10999.99,"4",IF(I13<=11999.99,"5",IF(I13<=12999.99,"6",IF(I13>=12999.99,"0",0)))))))) | AP13: =IF(I13<=12999.99,"0",IF(I13<=13999.99,"7",IF(I13<=14999.99,"8",IF(I13<=15999.99,"9",IF(I13<=16999.99,"10",IF(I13<=17999.99,"11",IF(I13>=17999.99,"0"))))))) | AQ13: =IF(I13<=17999.99,"0",IF(I13<=18999.99,"12",IF(I13<=19999.99,"13",IF(I13<=20999.99,"14",IF(I13<=21999.99,"15",IF(I13<=22999.99,"16",IF(I13<=23999.99,"17",IF(I13>=23999.99,"0")))))))) | AR13: =IF(I13<=23999.99,"0",IF(I13<=24999.99,"18",IF(I13<=25999.99,"19",IF(I13<=26999.99,"20",IF(I13<=27999.99,"21",IF(I13<=28999.99,"22",IF(I13<=29999.99,"23",IF(I13>=29999.99,"0")))))))) | AS13: =IF(I13<=29999.99,"0",IF(I13<=30999.99,"24",IF(I13<=31999.99,"25",IF(I13<=32999.99,"26",IF(I13<=33999.99,"27",IF(I13<=34999.99,"28",IF(I13>=35000,"29"))))))) | AT13: =IF(J13=1,"87.50",IF(J13=2,"100",IF(J13=3,"112.50",IF(J13=4,"125",IF(J13=5,"137.50",IF(J13=6,"150",IF(J13=7,"162.50",IF(J13=8,"175",0)))))))) | AU13: =IF(J13=9,"187.50",IF(J13=10,"200",IF(J13=11,"212.50",IF(J13=12,"225",IF(J13=13,"237.50",IF(J13=14,"250",IF(J13=15,"262.50",IF(J13=16,"275",0)))))))) | AV13: =IF(J13=17,"287.50",IF(J13=18,"300",IF(J13=19,"312.50",IF(J13=20,"325",IF(J13=21,"337.50",IF(J13=22,"350",IF(J13=23,"362.50",IF(J13=24,"375",0)))))))) | AW13: =IF(J13=25,"387.50",IF(J13=26,"400",IF(J13=27,"412.50",IF(J13=28,"425",IF(J13=29,"437.50",0))))) | AX13: =IF(I13=0,"0",IF(I13<=8999.99,"1",IF(I13<=9999.99,"2",IF(I13<=10999.99,"3",IF(I13<=11999.99,"4",IF(I13<=12999.99,"5",IF(I13<=13999.99,"6",IF(I13>=13999.99,"0",0)))))))) | AY13: =IF(I13<=13999.99,"0",IF(I13<=14999.99,"7",IF(I13<=15999.99,"8",IF(I13<=16999.99,"9",IF(I13<=17999.99,"10",IF(I13<=18999.99,"11",IF(I13>=18999.99,"0"))))))) | AZ13: =IF(I13<=18999.99,"0",IF(I13<=19999.99,"12",IF(I13<=20999.99,"13",IF(I13<=21999.99,"14",IF(I13<=22999.99,"15",IF(I13<=23999.99,"16",IF(I13<=24999.99,"17",IF(I13>=24999.99,"0")))))))) | BA13: =IF(I13<=24999.99,"0",IF(I13<=25999.99,"18",IF(I13<=26999.99,"19",IF(I13<=27999.99,"20",IF(I13<=28999.99,"21",IF(I13<=29999.99,"22",IF(I13<=30999.99,"23",IF(I13>=30999.99,"0")))))))) | BB13: =IF(I13<=30999.99,"0",IF(I13<=31999.99,"24",IF(I13<=32999.99,"25",IF(I13<=33999.99,"26",IF(I13<=34999.99,"27",IF(I13>=35000,"28")))))) | BC13: =IF(J13=1,"100",IF(J13=2,"112.50",IF(J13=3,"125",IF(J13=4,"137.50",IF(J13=5,"150",IF(J13=6,"162.50",IF(J13=7,"175",IF(J13=8,"187.50",0)))))))) | BD13: =IF(J13=9,"200",IF(J13=10,"212.50",IF(J13=11,"225",IF(J13=12,"237.50",IF(J13=13,"250",IF(J13=14,"262.50",IF(J13=15,"275",IF(J13=16,"287.50",0)))))))) | BE13: =IF(J13=17,"300",IF(J13=18,"312.50",IF(J13=19,"325",IF(J13=20,"337.50",IF(J13=21,"350",IF(J13=22,"362.50",IF(J13=23,"375",IF(J13=24,"387.50",0)))))))) | BF13: =IF(J13=25,"400",IF(J13=26,"412.50",IF(J13=27,"425",IF(J13=28,"437.50",0)))) | BG13: =IF(L13=2008,AK13+AL13+AM13+AN13,IF(L13=2009,AK13+AL13+AM13+AN13,IF(L13=2010,AK13+AL13+AM13+AN13,IF(L13=2011,AK13+AL13+AM13+AN13,IF(L13=2012,AK13+AL13+AM13+AN13,IF(L13=2013,AT13+AU13+AV13+AW13,IF(L13=2014,BC13+BD13+BE13+BF13,IF(L13=2015,BC13+BD13+BE13+BF13)))))))) | BH13: =IF(L13=2008,AK13+AL13+AM13+AN13,IF(L13=2009,AK13+AL13+AM13+AN13,IF(L13=2010,AK13+AL13+AM13+AN13,IF(L13=2011,AK13+AL13+AM13+AN13,IF(L13=2012,AK13+AL13+AM13+AN13,IF(L13=2013,AT13+AU13+AV13+AW13,IF(L13=2014,BC13+BD13+BE13+BF13,IF(L13=2015,BC13+BD13+BE13+BF13)))))))) | BI13: =IF(BH13=0,0,IF(BH13<=M13,BH13,IF(BH13>=M13,M13))) | BJ13: =CODE(B13:B20) | BK13: =ISBLANK(E13) | BL13: =CODE(E13) | BM13: =CHAR(BL13) | BN13: =ISBLANK(F13) | BO13: =ISBLANK(BS13) | BP13: =ISBLANK(BT13) | BQ13: =ISBLANK(G13) | BR13: =TEXT(BT13,"MMDDYYYY")
A14: =A13+1 | J14: =IF(L14=2008,AF14+AG14+AH14+AI14+AJ14,IF(L14=2009,AF14+AG14+AH14+AI14+AJ14,IF(L14=2010,AF14+AG14+AH14+AI14+AJ14,IF(L14=2011,AF14+AG14+AH14+AI14+AJ14,IF(L14=2012,AF14+AG14+AH14+AI14+AJ14,IF(L14=2013,AO14+AP14+AQ14+AR14+AS14,IF(L14=2014,AX14+AY14+AZ14+BA14+BB14,IF(L14=2015,AX14+AY14+AZ14+BA14+BB14)))))))) | K14: =K13 | L14: =L13 | M14: =M13 | N14: =IF(I14=0,"0",IF(I14<=4999.99,"1",IF(I14<=5999.99,"2",IF(I14<=6999.99,"3",IF(I14<=7999.99,"4",IF(I14<=8999.99,"5",IF(I14<=9999.99,"6",IF(I14>=9999.99,"0",0)))))))) | O14: =IF(I14<=9999.99,"0",IF(I14<=10999.99,"7",IF(I14<=11999.99,"8",IF(I14<=12999.99,"9",IF(I14<=13999.99,"10",IF(I14<=14999.99,"11",IF(I14>=14999.99,"0"))))))) | P14: =IF(I14<=14999.99,"0",IF(I14>=15000,"12")) | Q14: =IF(J14=1,"50",IF(J14=2,"62.50",IF(J14=3,"75",IF(J14=4,"87.5",IF(J14=5,"100",IF(J14=6,"112.50",IF(J14=7,"125",IF(J14=8,"137.50",0)))))))) | R14: =IF(J14=9,"150",IF(J14=10,"162.50",IF(J14=11,"175",IF(J14=12,"187.50",0)))) | S14: =IF(I14=0,"0",IF(I14<=4999.99,"1",IF(I14<=5999.99,"2",IF(I14<=6999.99,"3",IF(I14<=7999.99,"4",IF(I14<=8999.99,"5",IF(I14<=9999.99,"6",IF(I14>=9999.99,"0",0)))))))) | T14: =IF(I14<=9999.99,"0",IF(I14<=10999.99,"7",IF(I14<=11999.99,"8",IF(I14<=12999.99,"9",IF(I14<=13999.99,"10",IF(I14<=14999.99,"11",IF(I14>=14999.99,"0"))))))) | U14: =IF(I14<=14999.99,"0",IF(I14<=15999.99,"12",IF(I14<=16999.99,"13",IF(I14<=17999.99,"14",IF(I14<=18999.99,"15",IF(I14<=19999.99,"16",IF(I14>=20000,"17"))))))) | V14: =IF(J14=1,"50",IF(J14=2,"62.50",IF(J14=3,"75",IF(J14=4,"87.5",IF(J14=5,"100",IF(J14=6,"112.50",IF(J14=7,"125",IF(J14=8,"137.50",0)))))))) | W14: =IF(J14=9,"150",IF(J14=10,"162.50",IF(J14=11,"175",IF(J14=12,"187.50",IF(J14=13,"200",IF(J14=14,"212.5",IF(J14=15,"225",IF(J14=16,"237.5",0)))))))) | X14: =IF(J14=17,"250",0) | Y14: =IF(I14=0,"0",IF(I14<=4999.99,"1",IF(I14<=5999.99,"2",IF(I14<=6999.99,"3",IF(I14<=7999.99,"4",IF(I14<=8999.99,"5",IF(I14<=9999.99,"6",IF(I14>=9999.99,"0",0)))))))) | Z14: =IF(I14<=9999.99,"0",IF(I14<=10999.99,"7",IF(I14<=11999.99,"8",IF(I14<=12999.99,"9",IF(I14<=13999.99,"10",IF(I14<=14999.99,"11",IF(I14>=14999.99,"0"))))))) | AA14: =IF(I14<=14999.99,"0",IF(I14<=15999.99,"12",IF(I14<=16999.99,"13",IF(I14<=17999.99,"14",IF(I14<=18999.99,"15",IF(I14<=19999.99,"16",IF(I14<=20999.99,"17",IF(I14>=20999.99,"0")))))))) | AB14: =IF(I14<=20999.99,"0",IF(I14<=21999.99,"18",IF(I14<=22999.99,"19",IF(I14<=23999.99,"20",IF(I14<=24999.99,"21",IF(I14>=25000,"22")))))) | AC14: =IF(J14=1,"50",IF(J14=2,"62.50",IF(J14=3,"75",IF(J14=4,"87.5",IF(J14=5,"100",IF(J14=6,"112.50",IF(J14=7,"125",IF(J14=8,"137.50",0)))))))) | AD14: =IF(J14=9,"150",IF(J14=10,"162.50",IF(J14=11,"175",IF(J14=12,"187.50",IF(J14=13,"200",IF(J14=14,"212.5",IF(J14=15,"225",IF(J14=16,"237.5",0)))))))) | AE14: =IF(J14=17,"250",IF(J14=18,"262.50",IF(J14=19,"275",IF(J14=20,"287.50",IF(J14=21,"300",IF(J14=22,"312.50",0)))))) | AF14: =IF(I14=0,"0",IF(I14<=4999.99,"1",IF(I14<=5999.99,"2",IF(I14<=6999.99,"3",IF(I14<=7999.99,"4",IF(I14<=8999.99,"5",IF(I14<=9999.99,"6",IF(I14>=9999.99,"0",0)))))))) | AG14: =IF(I14<=9999.99,"0",IF(I14<=10999.99,"7",IF(I14<=11999.99,"8",IF(I14<=12999.99,"9",IF(I14<=13999.99,"10",IF(I14<=14999.99,"11",IF(I14>=14999.99,"0"))))))) | AH14: =IF(I14<=14999.99,"0",IF(I14<=15999.99,"12",IF(I14<=16999.99,"13",IF(I14<=17999.99,"14",IF(I14<=18999.99,"15",IF(I14<=19999.99,"16",IF(I14<=20999.99,"17",IF(I14>=20999.99,"0")))))))) | AI14: =IF(I14<=20999.99,"0",IF(I14<=21999.99,"18",IF(I14<=22999.99,"19",IF(I14<=23999.99,"20",IF(I14<=24999.99,"21",IF(I14<=25999.99,"22",IF(I14<=26999.99,"23",IF(I14>=26999.99,"0")))))))) | AJ14: =IF(I14<=26999.99,"0",IF(I14<=27999.99,"24",IF(I14<=28999.99,"25",IF(I14<=29999.99,"26",IF(I14>=30000,"27"))))) | AK14: =IF(J14=1,"50",IF(J14=2,"62.50",IF(J14=3,"75",IF(J14=4,"87.5",IF(J14=5,"100",IF(J14=6,"112.50",IF(J14=7,"125",IF(J14=8,"137.50",0)))))))) | AL14: =IF(J14=9,"150",IF(J14=10,"162.50",IF(J14=11,"175",IF(J14=12,"187.50",IF(J14=13,"200",IF(J14=14,"212.5",IF(J14=15,"225",IF(J14=16,"237.5",0)))))))) | AM14: =IF(J14=17,"250",IF(J14=18,"262.50",IF(J14=19,"275",IF(J14=20,"287.50",IF(J14=21,"300",IF(J14=22,"312.50",IF(J14=23,"325",IF(J14=24,"337.50",0)))))))) | AN14: =IF(J14=25,"350",IF(J14=26,"362.50",IF(J14=27,"375",0))) | AO14: =IF(I14=0,"0",IF(I14<=7999.99,"1",IF(I14<=8999.99,"2",IF(I14<=9999.99,"3",IF(I14<=10999.99,"4",IF(I14<=11999.99,"5",IF(I14<=12999.99,"6",IF(I14>=12999.99,"0",0)))))))) | AP14: =IF(I14<=12999.99,"0",IF(I14<=13999.99,"7",IF(I14<=14999.99,"8",IF(I14<=15999.99,"9",IF(I14<=16999.99,"10",IF(I14<=17999.99,"11",IF(I14>=17999.99,"0"))))))) | AQ14: =IF(I14<=17999.99,"0",IF(I14<=18999.99,"12",IF(I14<=19999.99,"13",IF(I14<=20999.99,"14",IF(I14<=21999.99,"15",IF(I14<=22999.99,"16",IF(I14<=23999.99,"17",IF(I14>=23999.99,"0")))))))) | AR14: =IF(I14<=23999.99,"0",IF(I14<=24999.99,"18",IF(I14<=25999.99,"19",IF(I14<=26999.99,"20",IF(I14<=27999.99,"21",IF(I14<=28999.99,"22",IF(I14<=29999.99,"23",IF(I14>=29999.99,"0")))))))) | AS14: =IF(I14<=29999.99,"0",IF(I14<=30999.99,"24",IF(I14<=31999.99,"25",IF(I14<=32999.99,"26",IF(I14<=33999.99,"27",IF(I14<=34999.99,"28",IF(I14>=35000,"29"))))))) | AT14: =IF(J14=1,"87.50",IF(J14=2,"100",IF(J14=3,"112.50",IF(J14=4,"125",IF(J14=5,"137.50",IF(J14=6,"150",IF(J14=7,"162.50",IF(J14=8,"175",0)))))))) | AU14: =IF(J14=9,"187.50",IF(J14=10,"200",IF(J14=11,"212.50",IF(J14=12,"225",IF(J14=13,"237.50",IF(J14=14,"250",IF(J14=15,"262.50",IF(J14=16,"275",0)))))))) | AV14: =IF(J14=17,"287.50",IF(J14=18,"300",IF(J14=19,"312.50",IF(J14=20,"325",IF(J14=21,"337.50",IF(J14=22,"350",IF(J14=23,"362.50",IF(J14=24,"375",0)))))))) | AW14: =IF(J14=25,"387.50",IF(J14=26,"400",IF(J14=27,"412.50",IF(J14=28,"425",IF(J14=29,"437.50",0))))) | AX14: =IF(I14=0,"0",IF(I14<=8999.99,"1",IF(I14<=9999.99,"2",IF(I14<=10999.99,"3",IF(I14<=11999.99,"4",IF(I14<=12999.99,"5",IF(I14<=13999.99,"6",IF(I14>=13999.99,"0",0)))))))) | AY14: =IF(I14<=13999.99,"0",IF(I14<=14999.99,"7",IF(I14<=15999.99,"8",IF(I14<=16999.99,"9",IF(I14<=17999.99,"10",IF(I14<=18999.99,"11",IF(I14>=18999.99,"0"))))))) | AZ14: =IF(I14<=18999.99,"0",IF(I14<=19999.99,"12",IF(I14<=20999.99,"13",IF(I14<=21999.99,"14",IF(I14<=22999.99,"15",IF(I14<=23999.99,"16",IF(I14<=24999.99,"17",IF(I14>=24999.99,"0")))))))) | BA14: =IF(I14<=24999.99,"0",IF(I14<=25999.99,"18",IF(I14<=26999.99,"19",IF(I14<=27999.99,"20",IF(I14<=28999.99,"21",IF(I14<=29999.99,"22",IF(I14<=30999.99,"23",IF(I14>=30999.99,"0")))))))) | BB14: =IF(I14<=30999.99,"0",IF(I14<=31999.99,"24",IF(I14<=32999.99,"25",IF(I14<=33999.99,"26",IF(I14<=34999.99,"27",IF(I14>=35000,"28")))))) | BC14: =IF(J14=1,"100",IF(J14=2,"112.50",IF(J14=3,"125",IF(J14=4,"137.50",IF(J14=5,"150",IF(J14=6,"162.50",IF(J14=7,"175",IF(J14=8,"187.50",0)))))))) | BD14: =IF(J14=9,"200",IF(J14=10,"212.50",IF(J14=11,"225",IF(J14=12,"237.50",IF(J14=13,"250",IF(J14=14,"262.50",IF(J14=15,"275",IF(J14=16,"287.50",0)))))))) | BE14: =IF(J14=17,"300",IF(J14=18,"312.50",IF(J14=19,"325",IF(J14=20,"337.50",IF(J14=21,"350",IF(J14=22,"362.50",IF(J14=23,"375",IF(J14=24,"387.50",0)))))))) | BF14: =IF(J14=25,"400",IF(J14=26,"412.50",IF(J14=27,"425",IF(J14=28,"437.50",0)))) | BG14: =IF(L14=2008,AK14+AL14+AM14+AN14,IF(L14=2009,AK14+AL14+AM14+AN14,IF(L14=2010,AK14+AL14+AM14+AN14,IF(L14=2011,AK14+AL14+AM14+AN14,IF(L14=2012,AK14+AL14+AM14+AN14,IF(L14=2013,AT14+AU14+AV14+AW14,IF(L14=2014,BC14+BD14+BE14+BF14,IF(L14=2015,BC14+BD14+BE14+BF14)))))))) | BH14: =IF(L14=2008,AK14+AL14+AM14+AN14,IF(L14=2009,AK14+AL14+AM14+AN14,IF(L14=2010,AK14+AL14+AM14+AN14,IF(L14=2011,AK14+AL14+AM14+AN14,IF(L14=2012,AK14+AL14+AM14+AN14,IF(L14=2013,AT14+AU14+AV14+AW14,IF(L14=2014,BC14+BD14+BE14+BF14,IF(L14=2015,BC14+BD14+BE14+BF14)))))))) | BI14: =IF(BH14=0,0,IF(BH14<=M14,BH14,IF(BH14>=M14,M14))) | BJ14: =CODE(B14:B20) | BK14: =ISBLANK(E14) | BL14: =CODE(E14) | BM14: =CHAR(BL14) | BN14: =ISBLANK(F14) | BO14: =ISBLANK(BS14) | BP14: =ISBLANK(BT14) | BQ14: =ISBLANK(G14) | BR14: =TEXT(BT14,"MMDDYYYY")
A15: =A14+1 | J15: =IF(L15=2008,AF15+AG15+AH15+AI15+AJ15,IF(L15=2009,AF15+AG15+AH15+AI15+AJ15,IF(L15=2010,AF15+AG15+AH15+AI15+AJ15,IF(L15=2011,AF15+AG15+AH15+AI15+AJ15,IF(L15=2012,AF15+AG15+AH15+AI15+AJ15,IF(L15=2013,AO15+AP15+AQ15+AR15+AS15,IF(L15=2014,AX15+AY15+AZ15+BA15+BB15,IF(L15=2015,AX15+AY15+AZ15+BA15+BB15)))))))) | K15: =K14 | L15: =L14 | M15: =M14 | N15: =IF(I15=0,"0",IF(I15<=4999.99,"1",IF(I15<=5999.99,"2",IF(I15<=6999.99,"3",IF(I15<=7999.99,"4",IF(I15<=8999.99,"5",IF(I15<=9999.99,"6",IF(I15>=9999.99,"0",0)))))))) | O15: =IF(I15<=9999.99,"0",IF(I15<=10999.99,"7",IF(I15<=11999.99,"8",IF(I15<=12999.99,"9",IF(I15<=13999.99,"10",IF(I15<=14999.99,"11",IF(I15>=14999.99,"0"))))))) | P15: =IF(I15<=14999.99,"0",IF(I15>=15000,"12")) | Q15: =IF(J15=1,"50",IF(J15=2,"62.50",IF(J15=3,"75",IF(J15=4,"87.5",IF(J15=5,"100",IF(J15=6,"112.50",IF(J15=7,"125",IF(J15=8,"137.50",0)))))))) | R15: =IF(J15=9,"150",IF(J15=10,"162.50",IF(J15=11,"175",IF(J15=12,"187.50",0)))) | S15: =IF(I15=0,"0",IF(I15<=4999.99,"1",IF(I15<=5999.99,"2",IF(I15<=6999.99,"3",IF(I15<=7999.99,"4",IF(I15<=8999.99,"5",IF(I15<=9999.99,"6",IF(I15>=9999.99,"0",0)))))))) | T15: =IF(I15<=9999.99,"0",IF(I15<=10999.99,"7",IF(I15<=11999.99,"8",IF(I15<=12999.99,"9",IF(I15<=13999.99,"10",IF(I15<=14999.99,"11",IF(I15>=14999.99,"0"))))))) | U15: =IF(I15<=14999.99,"0",IF(I15<=15999.99,"12",IF(I15<=16999.99,"13",IF(I15<=17999.99,"14",IF(I15<=18999.99,"15",IF(I15<=19999.99,"16",IF(I15>=20000,"17"))))))) | V15: =IF(J15=1,"50",IF(J15=2,"62.50",IF(J15=3,"75",IF(J15=4,"87.5",IF(J15=5,"100",IF(J15=6,"112.50",IF(J15=7,"125",IF(J15=8,"137.50",0)))))))) | W15: =IF(J15=9,"150",IF(J15=10,"162.50",IF(J15=11,"175",IF(J15=12,"187.50",IF(J15=13,"200",IF(J15=14,"212.5",IF(J15=15,"225",IF(J15=16,"237.5",0)))))))) | X15: =IF(J15=17,"250",0) | Y15: =IF(I15=0,"0",IF(I15<=4999.99,"1",IF(I15<=5999.99,"2",IF(I15<=6999.99,"3",IF(I15<=7999.99,"4",IF(I15<=8999.99,"5",IF(I15<=9999.99,"6",IF(I15>=9999.99,"0",0)))))))) | Z15: =IF(I15<=9999.99,"0",IF(I15<=10999.99,"7",IF(I15<=11999.99,"8",IF(I15<=12999.99,"9",IF(I15<=13999.99,"10",IF(I15<=14999.99,"11",IF(I15>=14999.99,"0"))))))) | AA15: =IF(I15<=14999.99,"0",IF(I15<=15999.99,"12",IF(I15<=16999.99,"13",IF(I15<=17999.99,"14",IF(I15<=18999.99,"15",IF(I15<=19999.99,"16",IF(I15<=20999.99,"17",IF(I15>=20999.99,"0")))))))) | AB15: =IF(I15<=20999.99,"0",IF(I15<=21999.99,"18",IF(I15<=22999.99,"19",IF(I15<=23999.99,"20",IF(I15<=24999.99,"21",IF(I15>=25000,"22")))))) | AC15: =IF(J15=1,"50",IF(J15=2,"62.50",IF(J15=3,"75",IF(J15=4,"87.5",IF(J15=5,"100",IF(J15=6,"112.50",IF(J15=7,"125",IF(J15=8,"137.50",0)))))))) | AD15: =IF(J15=9,"150",IF(J15=10,"162.50",IF(J15=11,"175",IF(J15=12,"187.50",IF(J15=13,"200",IF(J15=14,"212.5",IF(J15=15,"225",IF(J15=16,"237.5",0)))))))) | AE15: =IF(J15=17,"250",IF(J15=18,"262.50",IF(J15=19,"275",IF(J15=20,"287.50",IF(J15=21,"300",IF(J15=22,"312.50",0)))))) | AF15: =IF(I15=0,"0",IF(I15<=4999.99,"1",IF(I15<=5999.99,"2",IF(I15<=6999.99,"3",IF(I15<=7999.99,"4",IF(I15<=8999.99,"5",IF(I15<=9999.99,"6",IF(I15>=9999.99,"0",0)))))))) | AG15: =IF(I15<=9999.99,"0",IF(I15<=10999.99,"7",IF(I15<=11999.99,"8",IF(I15<=12999.99,"9",IF(I15<=13999.99,"10",IF(I15<=14999.99,"11",IF(I15>=14999.99,"0"))))))) | AH15: =IF(I15<=14999.99,"0",IF(I15<=15999.99,"12",IF(I15<=16999.99,"13",IF(I15<=17999.99,"14",IF(I15<=18999.99,"15",IF(I15<=19999.99,"16",IF(I15<=20999.99,"17",IF(I15>=20999.99,"0")))))))) | AI15: =IF(I15<=20999.99,"0",IF(I15<=21999.99,"18",IF(I15<=22999.99,"19",IF(I15<=23999.99,"20",IF(I15<=24999.99,"21",IF(I15<=25999.99,"22",IF(I15<=26999.99,"23",IF(I15>=26999.99,"0")))))))) | AJ15: =IF(I15<=26999.99,"0",IF(I15<=27999.99,"24",IF(I15<=28999.99,"25",IF(I15<=29999.99,"26",IF(I15>=30000,"27"))))) | AK15: =IF(J15=1,"50",IF(J15=2,"62.50",IF(J15=3,"75",IF(J15=4,"87.5",IF(J15=5,"100",IF(J15=6,"112.50",IF(J15=7,"125",IF(J15=8,"137.50",0)))))))) | AL15: =IF(J15=9,"150",IF(J15=10,"162.50",IF(J15=11,"175",IF(J15=12,"187.50",IF(J15=13,"200",IF(J15=14,"212.5",IF(J15=15,"225",IF(J15=16,"237.5",0)))))))) | AM15: =IF(J15=17,"250",IF(J15=18,"262.50",IF(J15=19,"275",IF(J15=20,"287.50",IF(J15=21,"300",IF(J15=22,"312.50",IF(J15=23,"325",IF(J15=24,"337.50",0)))))))) | AN15: =IF(J15=25,"350",IF(J15=26,"362.50",IF(J15=27,"375",0))) | AO15: =IF(I15=0,"0",IF(I15<=7999.99,"1",IF(I15<=8999.99,"2",IF(I15<=9999.99,"3",IF(I15<=10999.99,"4",IF(I15<=11999.99,"5",IF(I15<=12999.99,"6",IF(I15>=12999.99,"0",0)))))))) | AP15: =IF(I15<=12999.99,"0",IF(I15<=13999.99,"7",IF(I15<=14999.99,"8",IF(I15<=15999.99,"9",IF(I15<=16999.99,"10",IF(I15<=17999.99,"11",IF(I15>=17999.99,"0"))))))) | AQ15: =IF(I15<=17999.99,"0",IF(I15<=18999.99,"12",IF(I15<=19999.99,"13",IF(I15<=20999.99,"14",IF(I15<=21999.99,"15",IF(I15<=22999.99,"16",IF(I15<=23999.99,"17",IF(I15>=23999.99,"0")))))))) | AR15: =IF(I15<=23999.99,"0",IF(I15<=24999.99,"18",IF(I15<=25999.99,"19",IF(I15<=26999.99,"20",IF(I15<=27999.99,"21",IF(I15<=28999.99,"22",IF(I15<=29999.99,"23",IF(I15>=29999.99,"0")))))))) | AS15: =IF(I15<=29999.99,"0",IF(I15<=30999.99,"24",IF(I15<=31999.99,"25",IF(I15<=32999.99,"26",IF(I15<=33999.99,"27",IF(I15<=34999.99,"28",IF(I15>=35000,"29"))))))) | AT15: =IF(J15=1,"87.50",IF(J15=2,"100",IF(J15=3,"112.50",IF(J15=4,"125",IF(J15=5,"137.50",IF(J15=6,"150",IF(J15=7,"162.50",IF(J15=8,"175",0)))))))) | AU15: =IF(J15=9,"187.50",IF(J15=10,"200",IF(J15=11,"212.50",IF(J15=12,"225",IF(J15=13,"237.50",IF(J15=14,"250",IF(J15=15,"262.50",IF(J15=16,"275",0)))))))) | AV15: =IF(J15=17,"287.50",IF(J15=18,"300",IF(J15=19,"312.50",IF(J15=20,"325",IF(J15=21,"337.50",IF(J15=22,"350",IF(J15=23,"362.50",IF(J15=24,"375",0)))))))) | AW15: =IF(J15=25,"387.50",IF(J15=26,"400",IF(J15=27,"412.50",IF(J15=28,"425",IF(J15=29,"437.50",0))))) | AX15: =IF(I15=0,"0",IF(I15<=8999.99,"1",IF(I15<=9999.99,"2",IF(I15<=10999.99,"3",IF(I15<=11999.99,"4",IF(I15<=12999.99,"5",IF(I15<=13999.99,"6",IF(I15>=13999.99,"0",0)))))))) | AY15: =IF(I15<=13999.99,"0",IF(I15<=14999.99,"7",IF(I15<=15999.99,"8",IF(I15<=16999.99,"9",IF(I15<=17999.99,"10",IF(I15<=18999.99,"11",IF(I15>=18999.99,"0"))))))) | AZ15: =IF(I15<=18999.99,"0",IF(I15<=19999.99,"12",IF(I15<=20999.99,"13",IF(I15<=21999.99,"14",IF(I15<=22999.99,"15",IF(I15<=23999.99,"16",IF(I15<=24999.99,"17",IF(I15>=24999.99,"0")))))))) | BA15: =IF(I15<=24999.99,"0",IF(I15<=25999.99,"18",IF(I15<=26999.99,"19",IF(I15<=27999.99,"20",IF(I15<=28999.99,"21",IF(I15<=29999.99,"22",IF(I15<=30999.99,"23",IF(I15>=30999.99,"0")))))))) | BB15: =IF(I15<=30999.99,"0",IF(I15<=31999.99,"24",IF(I15<=32999.99,"25",IF(I15<=33999.99,"26",IF(I15<=34999.99,"27",IF(I15>=35000,"28")))))) | BC15: =IF(J15=1,"100",IF(J15=2,"112.50",IF(J15=3,"125",IF(J15=4,"137.50",IF(J15=5,"150",IF(J15=6,"162.50",IF(J15=7,"175",IF(J15=8,"187.50",0)))))))) | BD15: =IF(J15=9,"200",IF(J15=10,"212.50",IF(J15=11,"225",IF(J15=12,"237.50",IF(J15=13,"250",IF(J15=14,"262.50",IF(J15=15,"275",IF(J15=16,"287.50",0)))))))) | BE15: =IF(J15=17,"300",IF(J15=18,"312.50",IF(J15=19,"325",IF(J15=20,"337.50",IF(J15=21,"350",IF(J15=22,"362.50",IF(J15=23,"375",IF(J15=24,"387.50",0)))))))) | BF15: =IF(J15=25,"400",IF(J15=26,"412.50",IF(J15=27,"425",IF(J15=28,"437.50",0)))) | BG15: =IF(L15=2008,AK15+AL15+AM15+AN15,IF(L15=2009,AK15+AL15+AM15+AN15,IF(L15=2010,AK15+AL15+AM15+AN15,IF(L15=2011,AK15+AL15+AM15+AN15,IF(L15=2012,AK15+AL15+AM15+AN15,IF(L15=2013,AT15+AU15+AV15+AW15,IF(L15=2014,BC15+BD15+BE15+BF15,IF(L15=2015,BC15+BD15+BE15+BF15)))))))) | BH15: =IF(L15=2008,AK15+AL15+AM15+AN15,IF(L15=2009,AK15+AL15+AM15+AN15,IF(L15=2010,AK15+AL15+AM15+AN15,IF(L15=2011,AK15+AL15+AM15+AN15,IF(L15=2012,AK15+AL15+AM15+AN15,IF(L15=2013,AT15+AU15+AV15+AW15,IF(L15=2014,BC15+BD15+BE15+BF15,IF(L15=2015,BC15+BD15+BE15+BF15)))))))) | BI15: =IF(BH15=0,0,IF(BH15<=M15,BH15,IF(BH15>=M15,M15))) | BJ15: =CODE(B15:B20) | BK15: =ISBLANK(E15) | BL15: =CODE(E15) | BM15: =CHAR(BL15) | BN15: =ISBLANK(F15) | BO15: =ISBLANK(BS15) | BP15: =ISBLANK(BT15) | BQ15: =ISBLANK(G15) | BR15: =TEXT(BT15,"MMDDYYYY")
